Workbook

Sheet PLAYGROUP
F2: 1ST TERM | I2: 2ND TERM | N2: 3RD TERM | S2: TOTAL | T2: BALANCE | U2: EXPECTED
A3: NAME OF LEARNER | B3: ADM | C3: D/B | D3: B/F | E3: FEES | F3: COLLECTED | G3: BALANCE | H3: EXPECTED | I3: B/F | J3: FEES | K3: COLLECTED | L3: BALANCE | M3: EXPECTED | N3: B/F | O3: FEES | P3: TOTAL | Q3: BALANCE | R3: EXPECTED
A4: IVY JEPKOECH | B4: 0330 | C4: D | D4: 0 | E4: 12600 | F4: =E4 -> 12600 | G4: =H4+D4-F4 -> -3100 | H4: 9500 | I4: =G4 -> -3100 | K4: =J4 -> 0 | L4: =M4+I4-K4 -> 900 | M4: 4000 | N4: =L4 -> 900 | P4: =O4 -> 0 | Q4: =R4+N4-P4 -> 2900 | R4: 2000
A5: BREVINE KIBIWOTT | B5: 0333 | C5: D | D5: 0 | E5: 2000 | F5: =E5 -> 2000 | G5: =H5+D5-F5 -> 7500 | H5: 9500 | I5: =G5 -> 7500 | J5: 7000 | K5: =J5 -> 7000 | L5: =M5+I5-K5 -> 4500 | M5: 4000 | N5: =L5 -> 4500 | O5: 5500 | P5: =O5 -> 5500 | Q5: =R5+N5-P5 -> 1000 | R5: 2000
A6: BRIAN KIPKEMBOI | B6: 0348 | C6: D | D6: 0 | E6: 2000 | F6: =E6 -> 2000 | G6: =H6+D6-F6 -> 7500 | H6: 9500 | I6: =G6 -> 7500 | J6: 13500 | K6: =J6 -> 13500 | L6: =M6+I6-K6 -> -2000 | M6: 4000 | N6: =L6 -> -2000 | P6: =O6 -> 0 | Q6: =R6+N6-P6 -> 0 | R6: 2000
A7: DORCAS CHERUTO | B7: 0352 | C7: D | D7: 0 | E7: 9500 | F7: =E7 -> 9500 | G7: =H7+D7-F7 -> 0 | H7: 9500 | I7: =G7 -> 0 | J7: 4000 | K7: =J7 -> 4000 | L7: =M7+I7-K7 -> 0 | M7: 4000 | N7: =L7 -> 0 | O7: 2000 | P7: =O7 -> 2000 | Q7: =R7+N7-P7 -> 0 | R7: 2000
A8: LEYLA JERONO | B8: 0363 | C8: D | D8: 0 | E8: 9500 | F8: =E8 -> 9500 | G8: =H8+D8-F8 -> 0 | H8: 9500 | I8: =G8 -> 0 | J8: 4000 | K8: =J8 -> 4000 | L8: =M8+I8-K8 -> 0 | M8: 4000 | N8: =L8 -> 0 | P8: =O8 -> 0 | Q8: =R8+N8-P8 -> 2000 | R8: 2000
A9: NELVIN KIGEN | B9: 0364 | C9: D | D9: 0 | E9: 15500 | F9: =E9 -> 15500 | G9: =H9+D9-F9 -> -6000 | H9: 9500 | I9: =G9 -> -6000 | K9: =J9 -> 0 | L9: =M9+I9-K9 -> -2000 | M9: 4000 | N9: =L9 -> -2000 | P9: =O9 -> 0 | Q9: =R9+N9-P9 -> 0 | R9: 2000
A10: ALINA SARA | B10: 0377 | C10: D | D10: 0 | E10: 9500 | F10: =E10 -> 9500 | G10: =H10+D10-F10 -> 0 | H10: 9500 | I10: =G10 -> 0 | K10: =J10 -> 0 | L10: =M10+I10-K10 -> 4000 | M10: 4000 | N10: =L10 -> 4000 | P10: =O10 -> 0 | Q10: =R10+N10-P10 -> 4000 | R10: 0
A11: GIFT JEMUTAI | B11: 0387 | C11: D | D11: 0 | E11: 3500 | F11: =E11 -> 3500 | G11: =H11+D11-F11 -> 6000 | H11: 9500 | I11: =G11 -> 6000 | J11: 7000 | K11: =J11 -> 7000 | L11: =M11+I11-K11 -> 3000 | M11: 4000 | N11: =L11 -> 3000 | P11: =O11 -> 0 | Q11: =R11+N11-P11 -> 5000 | R11: 2000
A12: JOY JELAGAT | B12: 0390 | C12: D | D12: 0 | E12: 9500 | F12: =E12 -> 9500 | G12: =H12+D12-F12 -> 0 | H12: 9500 | I12: =G12 -> 0 | J12: 6000 | K12: =J12 -> 6000 | L12: =M12+I12-K12 -> -2000 | M12: 4000 | N12: =L12 -> -2000 | P12: =O12 -> 0 | Q12: =R12+N12-P12 -> 0 | R12: 2000
A13: NATHANIEL KIBET | B13: 0409 | C13: D | D13: 0 | E13: 9500 | F13: =E13 -> 9500 | G13: =H13+D13-F13 -> 0 | H13: 9500 | I13: =G13 -> 0 | J13: 4000 | K13: =J13 -> 4000 | L13: =M13+I13-K13 -> 0 | M13: 4000 | N13: =L13 -> 0 | P13: =O13 -> 0 | Q13: =R13+N13-P13 -> 2000 | R13: 2000
A14: NISHA KIMBERLY | B14: 0319 | C14: D | D14: 0 | E14: 9500 | F14: =E14 -> 9500 | G14: =H14+D14-F14 -> 0 | H14: 9500 | I14: =G14 -> 0 | J14: 4000 | K14: =J14 -> 4000 | L14: =M14+I14-K14 -> 0 | M14: 4000 | N14: =L14 -> 0 | O14: 1000 | P14: =O14 -> 1000 | Q14: =R14+N14-P14 -> 1000 | R14: 2000
A15: LIAM KIPROP | B15: 0445 | C15: D | D15: 0 | E15: 5000 | F15: =E15 -> 5000 | G15: =H15+D15-F15 -> 1650 | H15: 6650 | I15: =G15 -> 1650 | J15: 3650 | K15: =J15 -> 3650 | L15: =M15+I15-K15 -> 800 | M15: 2800 | N15: =L15 -> 800 | O15: 1000 | P15: =O15 -> 1000 | Q15: =R15+N15-P15 -> 1200 | R15: 1400
A16: GLEN KIMUTAI | B16: 0446 | C16: D | D16: 0 | E16: 2000 | F16: =E16 -> 2000 | G16: =H16+D16-F16 -> 4650 | H16: 6650 | I16: =G16 -> 4650 | J16: 4000 | K16: =J16 -> 4000 | L16: =M16+I16-K16 -> 3450 | M16: 2800 | N16: =L16 -> 3450 | P16: =O16 -> 0 | Q16: =R16+N16-P16 -> 5450 | R16: 2000
A17: LIAM KIPKEMBOI | B17: 0447 | C17: D | D17: 0 | E17: 2000 | F17: =E17 -> 2000 | G17: =H17+D17-F17 -> 7500 | H17: 9500 | I17: =G17 -> 7500 | K17: =J17 -> 0 | L17: =M17+I17-K17 -> 11500 | M17: 4000 | N17: =L17 -> 11500 | P17: =O17 -> 0 | Q17: =R17+N17-P17 -> 13500 | R17: 2000
A18: SHAM BETT | B18: 0448 | C18: D | D18: 0 | E18: 2000 | F18: =E18 -> 2000 | G18: =H18+D18-F18 -> 4650 | H18: 6650 | I18: =G18 -> 4650 | J18: 3000 | K18: =J18 -> 3000 | L18: =M18+I18-K18 -> 4450 | M18: 2800 | N18: =L18 -> 4450 | P18: =O18 -> 0 | Q18: =R18+N18-P18 -> 6450 | R18: 2000
A19: JADDAH JEPCHUMBA | B19: 0376 | C19: D | D19: 0 | E19: 6000 | F19: =E19 -> 6000 | G19: =H19+D19-F19 -> 650 | H19: 6650 | I19: =G19 -> 650 | J19: 650 | K19: =J19 -> 650 | L19: =M19+I19-K19 -> 2800 | M19: 2800 | N19: =L19 -> 2800 | P19: =O19 -> 0 | Q19: =R19+N19-P19 -> 4800 | R19: 2000
A20: BRAVIN MELI | B20: 0312 | C20: D | D20: 0 | E20: 6000 | F20: =E20 -> 6000 | G20: =H20+D20-F20 -> 3500 | H20: 9500 | I20: =G20 -> 3500 | J20: =3000+1000 -> 4000 | K20: =J20 -> 4000 | L20: =M20+I20-K20 -> 3500 | M20: 4000 | N20: =L20 -> 3500 | P20: =O20 -> 0 | Q20: =R20+N20-P20 -> 5500 | R20: 2000
A21: SHANNICE JERUTO | B21: 0442 | C21: D | D21: 0 | E21: 12600 | F21: =E21 -> 12600 | G21: =H21+D21-F21 -> -3100 | H21: 9500 | I21: =G21 -> -3100 | J21: 900 | K21: =J21 -> 900 | L21: =M21+I21-K21 -> 0 | M21: 4000 | N21: =L21 -> 0 | P21: =O21 -> 0 | Q21: =R21+N21-P21 -> 2000 | R21: 2000
A22: MALIA CHEPCHIRCHIR | B22: 0453 | C22: D | D22: 0 | E22: 6650 | F22: =E22 -> 6650 | G22: =H22+D22-F22 -> 2850 | H22: 9500 | I22: =G22 -> 2850 | J22: 6850 | K22: =J22 -> 6850 | L22: =M22+I22-K22 -> 0 | M22: 4000 | N22: =L22 -> 0 | O22: 2000 | P22: =O22 -> 2000 | Q22: =R22+N22-P22 -> 0 | R22: 2000
A23: EILA JEMUTAI | B23: 0459 | C23: D | D23: 0 | F23: =E23 -> 0 | G23: =H23+D23-F23 -> 0 | H23: 0 | I23: =G23 -> 0 | J23: 4000 | K23: =J23 -> 4000 | L23: =M23+I23-K23 -> 0 | M23: 4000 | N23: =L23 -> 0 | O23: 1000 | P23: =O23 -> 1000 | Q23: =R23+N23-P23 -> 1000 | R23: 2000
A24: ADRIEL KIPCHUMBA | B24: 0468 | C24: D | D24: 0 | F24: =E24 -> 0 | G24: =H24+D24-F24 -> 0 | H24: 0 | I24: =G24 -> 0 | J24: =2150+1350 -> 3500 | K24: =J24 -> 3500 | L24: =M24+I24-K24 -> 500 | M24: 4000 | N24: =L24 -> 500 | P24: =O24 -> 0 | Q24: =R24+N24-P24 -> 2500 | R24: 2000
A25: JILL SOGOMO | B25: 0471 | C25: D | D25: 0 | F25: =E25 -> 0 | G25: =H25+D25-F25 -> 0 | H25: 0 | I25: =G25 -> 0 | J25: 5750 | K25: =J25 -> 5750 | L25: =M25+I25-K25 -> -1750 | M25: 4000 | N25: =L25 -> -1750 | P25: =O25 -> 0 | Q25: =R25+N25-P25 -> 250 | R25: 2000
A26: LATIFFAH JELIMO | B26: 0485 | C26: D | D26: 0 | F26: =E26 -> 0 | G26: =H26+D26-F26 -> 0 | H26: 0 | I26: =G26 -> 0 | J26: 4000 | K26: =J26 -> 4000 | L26: =M26+I26-K26 -> 0 | M26: 4000 | N26: =L26 -> 0 | O26: 2000 | P26: =O26 -> 2000 | Q26: =R26+N26-P26 -> 0 | R26: 2000
A27: NIALL KIPKOGEI | B27: 0478 | C27: D | D27: 0 | F27: =E27 -> 0 | G27: =H27+D27-F27 -> 0 | H27: 0 | I27: =G27 -> 0 | J27: 4000 | K27: =J27 -> 4000 | L27: =M27+I27-K27 -> 0 | M27: 4000 | N27: =L27 -> 0 | P27: =O27 -> 0 | Q27: =R27+N27-P27 -> 2000 | R27: 2000
A28: BELLA CHEMUTAI | B28: 0486 | C28: D | D28: 0 | F28: =E28 -> 0 | G28: =H28+D28-F28 -> 0 | H28: 0 | I28: =G28 -> 0 | J28: =3150+850 -> 4000 | K28: =J28 -> 4000 | L28: =M28+I28-K28 -> 0 | M28: 4000 | N28: =L28 -> 0 | P28: =O28 -> 0 | Q28: =R28+N28-P28 -> 2000 | R28: 2000
A29: FELIX KIPTOO ROP | B29: 0487 | C29: D | D29: 0 | F29: =E29 -> 0 | G29: =H29+D29-F29 -> 0 | H29: 0 | I29: =G29 -> 0 | J29: 4000 | K29: =J29 -> 4000 | L29: =M29+I29-K29 -> 0 | M29: 4000 | N29: =L29 -> 0 | O29: 2000 | P29: =O29 -> 2000 | Q29: =R29+N29-P29 -> 0 | R29: 2000
A30: EVANA CHEBET | B30: 0492 | C30: D | D30: 0 | F30: =E30 -> 0 | G30: =H30+D30-F30 -> 0 | H30: 0 | I30: =G30 -> 0 | J30: 4000 | K30: =J30 -> 4000 | L30: =M30+I30-K30 -> 0 | M30: 4000 | N30: =L30 -> 0 | P30: =O30 -> 0 | Q30: =R30+N30-P30 -> 2000 | R30: 2000
A31: ANGIE JEBIWOT | B31: 0494 | C31: D | D31: 0 | F31: =E31 -> 0 | G31: =H31+D31-F31 -> 0 | H31: 0 | I31: =G31 -> 0 | J31: 4000 | K31: =J31 -> 4000 | L31: =M31+I31-K31 -> 0 | M31: 4000 | N31: =L31 -> 0 | P31: =O31 -> 0 | Q31: =R31+N31-P31 -> 2000 | R31: 2000
A32: ELLENA JEMUTAI YATOR | B32: 0487 | C32: D | D32: 0 | F32: =E32 -> 0 | G32: =H32+D32-F32 -> 0 | H32: 0 | I32: =G32 -> 0 | J32: 4000 | K32: =J32 -> 4000 | L32: =M32+I32-K32 -> 0 | M32: 4000 | N32: =L32 -> 0 | P32: =O32 -> 0 | Q32: =R32+N32-P32 -> 2000 | R32: 2000
A33: AYLAKNIGHT JERUTO | B33: 0495 | C33: D | D33: 0 | F33: =E33 -> 0 | G33: =H33+D33-F33 -> 0 | H33: 0 | I33: =G33 -> 0 | J33: 3300 | K33: =J33 -> 3300 | L33: =M33+I33-K33 -> 700 | M33: 4000 | N33: =L33 -> 700 | P33: =O33 -> 0 | Q33: =R33+N33-P33 -> 2700 | R33: 2000
A34: ETHAN MATETE | B34: 0496 | C34: D | D34: 0 | F34: =E34 -> 0 | G34: =H34+D34-F34 -> 0 | H34: 0 | I34: =G34 -> 0 | K34: =J34 -> 0 | L34: =M34+I34-K34 -> 2800 | M34: 2800 | N34: =L34 -> 2800 | P34: =O34 -> 0 | Q34: =R34+N34-P34 -> 4800 | R34: 2000
A35: REAGAN KIGEN | B35: 0462 | C35: D | D35: 0 | F35: =E35 -> 0 | G35: =H35+D35-F35 -> 0 | H35: 0 | I35: =G35 -> 0 | J35: 4000 | K35: =J35 -> 4000 | L35: =M35+I35-K35 -> 0 | M35: 4000 | N35: =L35 -> 0 | O35: 2000 | P35: =O35 -> 2000 | Q35: =R35+N35-P35 -> 0 | R35: 2000
A36: ZION KIPROP | B36: 0488 | C36: D | D36: 0 | F36: =E36 -> 0 | G36: =H36+D36-F36 -> 0 | H36: 0 | I36: =G36 -> 0 | J36: 1500 | K36: =J36 -> 1500 | L36: =M36+I36-K36 -> 2500 | M36: 4000 | N36: =L36 -> 2500 | O36: 2500 | P36: =O36 -> 2500 | Q36: =R36+N36-P36 -> 2000 | R36: 2000
A37: ZARIA CHELIMO | B37: 0489 | C37: D | D37: 0 | F37: =E37 -> 0 | G37: =H37+D37-F37 -> 0 | H37: 0 | I37: =G37 -> 0 | J37: 1500 | K37: =J37 -> 1500 | L37: =M37+I37-K37 -> 2500 | M37: 4000 | N37: =L37 -> 2500 | O37: 2500 | P37: =O37 -> 2500 | Q37: =R37+N37-P37 -> 2000 | R37: 2000
A38: KYLAH CHEPCHUMBA | B38: 0497 | C38: D | D38: 0 | F38: =E38 -> 0 | G38: =H38+D38-F38 -> 0 | H38: 0 | I38: =G38 -> 0 | J38: 4500 | K38: =J38 -> 4500 | L38: =M38+I38-K38 -> -1700 | M38: 2800 | N38: =L38 -> -1700 | P38: =O38 -> 0 | Q38: =R38+N38-P38 -> -300 | R38: 1400
A39: FABIAN KIMUTAI | B39: 0500 | C39: D | D39: 0 | F39: =E39 -> 0 | G39: =H39+D39-F39 -> 0 | H39: 0 | I39: =G39 -> 0 | J39: 0 | K39: =J39 -> 0 | L39: =M39+I39-K39 -> 2000 | M39: 2000 | N39: =L39 -> 2000 | P39: =O39 -> 0 | Q39: =R39+N39-P39 -> 4000 | R39: 2000
A40: BLESSING CHEPCHUMBA | B40: 0502 | C40: D | D40: 0 | F40: =E40 -> 0 | G40: =H40+D40-F40 -> 0 | H40: 0 | I40: =G40 -> 0 | J40: 0 | K40: =J40 -> 0 | L40: =M40+I40-K40 -> 0 | M40: 0 | N40: =L40 -> 0 | P40: =O40 -> 0 | Q40: =R40+N40-P40 -> 2000 | R40: 2000
A41: ASHER KIMUTAI | B41: 0508 | C41: D | D41: 0 | F41: =E41 -> 0 | G41: =H41+D41-F41 -> 0 | H41: 0 | I41: =G41 -> 0 | J41: 0 | K41: =J41 -> 0 | L41: =M41+I41-K41 -> 0 | M41: 0 | N41: =L41 -> 0 | O41: 2000 | P41: =O41 -> 2000 | Q41: =R41+N41-P41 -> 0 | R41: 2000
...

Sheet PP1
A2: NAME OF LEARNER | F2: 1ST TERM | L2: 2ND TERM | Q2: 3RD TERM | S2: TOTAL | T2: BALANCE | U2: EXPECTED
B3: ADM | C3: B/D | D3: B/F | E3: FEES | F3: TOTAL | G3: BALANCE | H3: EXPECTED | I3: B/F | J3: FEES | K3: TOTAL | L3: BALANCE | M3: EXPECTED | N3: B/F | O3: FEES | P3: TOTAL | Q3: BALANCE | R3: EXPECTED
A4: REENA CHEMUTAI | B4: 0296 | C4: D | E4: 9500 | F4: =E4 -> 9500 | G4: =H4+D4-F4 -> 0 | H4: 9500 | I4: =G4 -> 0 | J4: 2000 | K4: =J4 -> 2000 | L4: =M4+I4-K4 -> 2000 | M4: 4000 | N4: =L4 -> 2000 | O4: 2000 | P4: =O4 -> 2000 | Q4: =R4+N4-P4 -> 2000 | R4: 2000
A5: FIDEL KIPTOO | B5: 0297 | C5: D | E5: 9500 | F5: =E5 -> 9500 | G5: =H5+D5-F5 -> 0 | H5: 9500 | I5: =G5 -> 0 | J5: 2800 | K5: =J5 -> 2800 | L5: =M5+I5-K5 -> 1200 | M5: 4000 | N5: =L5 -> 1200 | O5: 1200 | P5: =O5 -> 1200 | Q5: =R5+N5-P5 -> 2000 | R5: 2000
A6: BEVAN KIBET | B6: 0298 | C6: D | D6: 8000 | F6: =E6 -> 0 | G6: =H6+D6-F6 -> 17500 | H6: 9500 | I6: =G6 -> 17500 | K6: =J6 -> 0 | L6: =M6+I6-K6 -> 17500 | M6: 0 | N6: =L6 -> 17500 | P6: =O6 -> 0 | Q6: =R6+N6-P6 -> 17500 | R6: 0
A7: BLESSED KIPCHUMBA | B7: 0299 | C7: D | D7: 1650 | E7: 8400 | F7: =E7 -> 8400 | G7: =H7+D7-F7 -> 2750 | H7: 9500 | I7: =G7 -> 2750 | J7: 5500 | K7: =J7 -> 5500 | L7: =M7+I7-K7 -> 1250 | M7: 4000 | N7: =L7 -> 1250 | P7: =O7 -> 0 | Q7: =R7+N7-P7 -> 3250 | R7: 2000
A8: DARIUS KIPKORIR | B8: 0300 | C8: D | D8: 50 | E8: 13500 | F8: =E8 -> 13500 | G8: =H8+D8-F8 -> -3950 | H8: 9500 | I8: =G8 -> -3950 | K8: =J8 -> 0 | L8: =M8+I8-K8 -> 50 | M8: 4000 | N8: =L8 -> 50 | P8: =O8 -> 0 | Q8: =R8+N8-P8 -> 2050 | R8: 2000
A9: ASBEL KIPROTICH | B9: 0301 | C9: D | E9: 9500 | F9: =E9 -> 9500 | G9: =H9+D9-F9 -> 0 | H9: 9500 | I9: =G9 -> 0 | J9: 3600 | K9: =J9 -> 3600 | L9: =M9+I9-K9 -> 400 | M9: 4000 | N9: =L9 -> 400 | O9: 400 | P9: =O9 -> 400 | Q9: =R9+N9-P9 -> 2000 | R9: 2000
A10: LIAM KIPKEMBOI | B10: 0302 | C10: D | D10: 2500 | F10: =E10 -> 0 | G10: =H10+D10-F10 -> 12000 | H10: 9500 | I10: =G10 -> 12000 | K10: =J10 -> 0 | L10: =M10+I10-K10 -> 16000 | M10: 4000 | N10: =L10 -> 16000 | P10: =O10 -> 0 | Q10: =R10+N10-P10 -> 16000 | R10: 0
A11: JESSY KIPROTICH | B11: 0303 | C11: D | E11: 9500 | F11: =E11 -> 9500 | G11: =H11+D11-F11 -> 0 | H11: 9500 | I11: =G11 -> 0 | J11: 4000 | K11: =J11 -> 4000 | L11: =M11+I11-K11 -> 0 | M11: 4000 | N11: =L11 -> 0 | P11: =O11 -> 0 | Q11: =R11+N11-P11 -> 2000 | R11: 2000
A12: GENESIS ODHIAMBO | B12: 0304 | C12: D | E12: 9500 | F12: =E12 -> 9500 | G12: =H12+D12-F12 -> 0 | H12: 9500 | I12: =G12 -> 0 | J12: 4000 | K12: =J12 -> 4000 | L12: =M12+I12-K12 -> 0 | M12: 4000 | N12: =L12 -> 0 | O12: 1000 | P12: =O12 -> 1000 | Q12: =R12+N12-P12 -> 1000 | R12: 2000
A13: PATIENCE JEPTOO | B13: 0305 | C13: D | E13: 9500 | F13: =E13 -> 9500 | G13: =H13+D13-F13 -> 0 | H13: 9500 | I13: =G13 -> 0 | J13: 6000 | K13: =J13 -> 6000 | L13: =M13+I13-K13 -> -2000 | M13: 4000 | N13: =L13 -> -2000 | P13: =O13 -> 0 | Q13: =R13+N13-P13 -> 0 | R13: 2000
A14: SASHA JELIMO | B14: 0306 | C14: D | E14: 9500 | F14: =E14 -> 9500 | G14: =H14+D14-F14 -> 0 | H14: 9500 | I14: =G14 -> 0 | J14: 4000 | K14: =J14 -> 4000 | L14: =M14+I14-K14 -> 0 | M14: 4000 | N14: =L14 -> 0 | P14: =O14 -> 0 | Q14: =R14+N14-P14 -> 2000 | R14: 2000
A15: MIKEL KIPKOECH | B15: 0307 | C15: D | E15: 5000 | F15: =E15 -> 5000 | G15: =H15+D15-F15 -> 4500 | H15: 9500 | I15: =G15 -> 4500 | K15: =J15 -> 0 | L15: =M15+I15-K15 -> 8500 | M15: 4000 | N15: =L15 -> 8500 | P15: =O15 -> 0 | Q15: =R15+N15-P15 -> 10500 | R15: 2000
A16: GILLIAN JEMUTAI | B16: 0308 | C16: D | E16: 9500 | F16: =E16 -> 9500 | G16: =H16+D16-F16 -> 0 | H16: 9500 | I16: =G16 -> 0 | J16: 2000 | K16: =J16 -> 2000 | L16: =M16+I16-K16 -> 2000 | M16: 4000 | N16: =L16 -> 2000 | O16: 2000 | P16: =O16 -> 2000 | Q16: =R16+N16-P16 -> 2000 | R16: 2000
A17: KAYDEN KIPROP | B17: 0309 | C17: D | E17: 7000 | F17: =E17 -> 7000 | G17: =H17+D17-F17 -> 2500 | H17: 9500 | I17: =G17 -> 2500 | J17: 6500 | K17: =J17 -> 6500 | L17: =M17+I17-K17 -> 0 | M17: 4000 | N17: =L17 -> 0 | P17: =O17 -> 0 | Q17: =R17+N17-P17 -> 2000 | R17: 2000
A18: BRIAN KIPKORIR | B18: 0310 | C18: D | F18: =E18 -> 0 | G18: =H18+D18-F18 -> 9500 | H18: 9500 | I18: =G18 -> 9500 | K18: =J18 -> 0 | L18: =M18+I18-K18 -> 13500 | M18: 4000 | N18: =L18 -> 13500 | P18: =O18 -> 0 | Q18: =R18+N18-P18 -> 13500 | R18: 0
A19: BRAVIN KIPKOECH | B19: 0311 | C19: D | E19: 9500 | F19: =E19 -> 9500 | G19: =H19+D19-F19 -> 0 | H19: 9500 | I19: =G19 -> 0 | J19: 4000 | K19: =J19 -> 4000 | L19: =M19+I19-K19 -> 0 | M19: 4000 | N19: =L19 -> 0 | P19: =O19 -> 0 | Q19: =R19+N19-P19 -> 2000 | R19: 2000
A20: ARYANNAH WANJIKU | B20: 0313 | C20: D | E20: 9500 | F20: =E20 -> 9500 | G20: =H20+D20-F20 -> 0 | H20: 9500 | I20: =G20 -> 0 | J20: 4000 | K20: =J20 -> 4000 | L20: =M20+I20-K20 -> 0 | M20: 4000 | N20: =L20 -> 0 | O20: 2000 | P20: =O20 -> 2000 | Q20: =R20+N20-P20 -> 0 | R20: 2000
A21: AIDEN KIPCHUMBA | B21: 0314 | C21: D | E21: 9500 | F21: =E21 -> 9500 | G21: =H21+D21-F21 -> 0 | H21: 9500 | I21: =G21 -> 0 | J21: 4000 | K21: =J21 -> 4000 | L21: =M21+I21-K21 -> 0 | M21: 4000 | N21: =L21 -> 0 | P21: =O21 -> 0 | Q21: =R21+N21-P21 -> 2000 | R21: 2000
A22: ADRIANNA JEPKOSGEI | B22: 0315 | C22: D | E22: 9500 | F22: =E22 -> 9500 | G22: =H22+D22-F22 -> 0 | H22: 9500 | I22: =G22 -> 0 | J22: 4000 | K22: =J22 -> 4000 | L22: =M22+I22-K22 -> 0 | M22: 4000 | N22: =L22 -> 0 | P22: =O22 -> 0 | Q22: =R22+N22-P22 -> 2000 | R22: 2000
A23: ABIGAEL KIPSARNO | B23: 0316 | C23: D | E23: 5500 | F23: =E23 -> 5500 | G23: =H23+D23-F23 -> 4000 | H23: 9500 | I23: =G23 -> 4000 | J23: =5000+700 -> 5700 | K23: =J23 -> 5700 | L23: =M23+I23-K23 -> 2300 | M23: 4000 | N23: =L23 -> 2300 | O23: 2500 | P23: =O23 -> 2500 | Q23: =R23+N23-P23 -> 1800 | R23: 2000
A24: ABIUD KIPSARNO | B24: 0317 | C24: D | E24: 5500 | F24: =E24 -> 5500 | G24: =H24+D24-F24 -> 4000 | H24: 9500 | I24: =G24 -> 4000 | J24: =5000+700 -> 5700 | K24: =J24 -> 5700 | L24: =M24+I24-K24 -> 2300 | M24: 4000 | N24: =L24 -> 2300 | O24: 2500 | P24: =O24 -> 2500 | Q24: =R24+N24-P24 -> 1800 | R24: 2000
A25: JODYANN JEROTICH | B25: 0318 | C25: D | E25: 7000 | F25: =E25 -> 7000 | G25: =H25+D25-F25 -> 2500 | H25: 9500 | I25: =G25 -> 2500 | J25: 6500 | K25: =J25 -> 6500 | L25: =M25+I25-K25 -> 0 | M25: 4000 | N25: =L25 -> 0 | P25: =O25 -> 0 | Q25: =R25+N25-P25 -> 2000 | R25: 2000
A26: ARYANNAH SHINNEL | B26: 0458 | C26: D | D26: 3000 | E26: 2000 | F26: =E26 -> 2000 | G26: =H26+D26-F26 -> 7650 | H26: 6650 | I26: =G26 -> 7650 | J26: 4000 | K26: =J26 -> 4000 | L26: =M26+I26-K26 -> 6450 | M26: 2800 | N26: =L26 -> 6450 | P26: =O26 -> 0 | Q26: =R26+N26-P26 -> 6450 | R26: 0
A27: ENOCK KIPRUTO | B27: 0400 | C27: D | E27: 9500 | F27: =E27 -> 9500 | G27: =H27+D27-F27 -> 0 | H27: 9500 | I27: =G27 -> 0 | J27: =1100+1000 -> 2100 | K27: =J27 -> 2100 | L27: =M27+I27-K27 -> 1900 | M27: 4000 | N27: =L27 -> 1900 | P27: =O27 -> 0 | Q27: =R27+N27-P27 -> 3900 | R27: 2000
A28: SHALINE JEPCHUMBA | B28: 0401 | C28: D | D28: 50 | E28: 15000 | F28: =E28 -> 15000 | G28: =H28+D28-F28 -> -5450 | H28: 9500 | I28: =G28 -> -5450 | K28: =J28 -> 0 | L28: =M28+I28-K28 -> -1450 | M28: 4000 | N28: =L28 -> -1450 | P28: =O28 -> 0 | Q28: =R28+N28-P28 -> 550 | R28: 2000
A29: SHALINE JEPCHUMBA KOSGEI | B29: 0402 | C29: D | E29: 9500 | F29: =E29 -> 9500 | G29: =H29+D29-F29 -> 0 | H29: 9500 | I29: =G29 -> 0 | J29: 4000 | K29: =J29 -> 4000 | L29: =M29+I29-K29 -> 0 | M29: 4000 | N29: =L29 -> 0 | P29: =O29 -> 0 | Q29: =R29+N29-P29 -> 2000 | R29: 2000
A30: BRIGID CHEROP | B30: 0403 | C30: D | E30: 9500 | F30: =E30 -> 9500 | G30: =H30+D30-F30 -> 0 | H30: 9500 | I30: =G30 -> 0 | J30: 4000 | K30: =J30 -> 4000 | L30: =M30+I30-K30 -> 0 | M30: 4000 | N30: =L30 -> 0 | O30: 2000 | P30: =O30 -> 2000 | Q30: =R30+N30-P30 -> 0 | R30: 2000
A31: BLESSING JERUTO KITUM | B31: 0320 | C31: D | E31: 8500 | F31: =E31 -> 8500 | G31: =H31+D31-F31 -> 1000 | H31: 9500 | I31: =G31 -> 1000 | J31: =4500+500 -> 5000 | K31: =J31 -> 5000 | L31: =M31+I31-K31 -> 0 | M31: 4000 | N31: =L31 -> 0 | P31: =O31 -> 0 | Q31: =R31+N31-P31 -> 2000 | R31: 2000
A32: TALIA JEPTOO | B32: 0331 | C32: D | E32: 9500 | F32: =E32 -> 9500 | G32: =H32+D32-F32 -> 0 | H32: 9500 | I32: =G32 -> 0 | J32: 4000 | K32: =J32 -> 4000 | L32: =M32+I32-K32 -> 0 | M32: 4000 | N32: =L32 -> 0 | O32: 1000 | P32: =O32 -> 1000 | Q32: =R32+N32-P32 -> 1000 | R32: 2000
A33: WISDOM ODHIAMBO | B33: 0329 | C33: D | E33: 6000 | F33: =E33 -> 6000 | G33: =H33+D33-F33 -> 3500 | H33: 9500 | I33: =G33 -> 3500 | J33: =5000+525+1500 -> 7025 | K33: =J33 -> 7025 | L33: =M33+I33-K33 -> 475 | M33: 4000 | N33: =L33 -> 475 | P33: =O33 -> 0 | Q33: =R33+N33-P33 -> 2475 | R33: 2000
A34: JACELYN JELAGAT | B34: 0340 | C34: D | E34: 9500 | F34: =E34 -> 9500 | G34: =H34+D34-F34 -> 0 | H34: 9500 | I34: =G34 -> 0 | J34: =2000+2050 -> 4050 | K34: =J34 -> 4050 | L34: =M34+I34-K34 -> -50 | M34: 4000 | N34: =L34 -> -50 | O34: 2000 | P34: =O34 -> 2000 | Q34: =R34+N34-P34 -> -50 | R34: 2000
A35: ADEN KIPRONO | B35: 0369 | C35: D | E35: 7500 | F35: =E35 -> 7500 | G35: =H35+D35-F35 -> 2000 | H35: 9500 | I35: =G35 -> 2000 | J35: 6000 | K35: =J35 -> 6000 | L35: =M35+I35-K35 -> 0 | M35: 4000 | N35: =L35 -> 0 | O35: 1200 | P35: =O35 -> 1200 | Q35: =R35+N35-P35 -> 800 | R35: 2000
A36: JAYDEN KIPRONO | B36: 0381 | C36: D | E36: 8850 | F36: =E36 -> 8850 | G36: =H36+D36-F36 -> 650 | H36: 9500 | I36: =G36 -> 650 | J36: 4650 | K36: =J36 -> 4650 | L36: =M36+I36-K36 -> 0 | M36: 4000 | N36: =L36 -> 0 | P36: =O36 -> 0 | Q36: =R36+N36-P36 -> 2000 | R36: 2000
A37: JAYDEN KIPCHIRCHIR | B37: 0386 | C37: D | E37: 7700 | F37: =E37 -> 7700 | G37: =H37+D37-F37 -> 1800 | H37: 9500 | I37: =G37 -> 1800 | J37: 1500 | K37: =J37 -> 1500 | L37: =M37+I37-K37 -> 4300 | M37: 4000 | N37: =L37 -> 4300 | P37: =O37 -> 0 | Q37: =R37+N37-P37 -> 6300 | R37: 2000
A38: ELLA JEBET | B38: 0404 | C38: D | E38: 9000 | F38: =E38 -> 9000 | G38: =H38+D38-F38 -> 500 | H38: 9500 | I38: =G38 -> 500 | J38: 4500 | K38: =J38 -> 4500 | L38: =M38+I38-K38 -> 0 | M38: 4000 | N38: =L38 -> 0 | O38: 1000 | P38: =O38 -> 1000 | Q38: =R38+N38-P38 -> 1000 | R38: 2000
A39: ABIGAEL JEPKORIR | B39: 0421 | C39: D | E39: 3550 | F39: =E39 -> 3550 | G39: =H39+D39-F39 -> 5950 | H39: 9500 | I39: =G39 -> 5950 | K39: =J39 -> 0 | L39: =M39+I39-K39 -> 9950 | M39: 4000 | N39: =L39 -> 9950 | P39: =O39 -> 0 | Q39: =R39+N39-P39 -> 11950 | R39: 2000
A40: ANNETTE JEBIWOTT | B40: 0435 | C40: D | E40: 7700 | F40: =E40 -> 7700 | G40: =H40+D40-F40 -> 1800 | H40: 9500 | I40: =G40 -> 1800 | J40: 6000 | K40: =J40 -> 6000 | L40: =M40+I40-K40 -> -200 | M40: 4000 | N40: =L40 -> -200 | P40: =O40 -> 0 | Q40: =R40+N40-P40 -> 1800 | R40: 2000
A41: ADRIAN KIPROP | B41: 0362 | C41: D | E41: 7000 | F41: =E41 -> 7000 | G41: =H41+D41-F41 -> 2500 | H41: 9500 | I41: =G41 -> 2500 | J41: 6500 | K41: =J41 -> 6500 | L41: =M41+I41-K41 -> 0 | M41: 4000 | N41: =L41 -> 0 | P41: =O41 -> 0 | Q41: =R41+N41-P41 -> 2000 | R41: 2000
...

Sheet PP2
A2: NAME OF LEARNER | F2: 1ST TERM | L2: 2ND TERM | Q2: 3RD TERM | S2: TOTAL | T2: BALANCE | U2: EXPECTED
B3: ADM | C3: B/D | D3: B/F | E3: FEES | F3: TOTAL | G3: BALANCE | H3: EXPECTED | I3: B/F | J3: FEES | K3: TOTAL | L3: BALANCE | M3: EXPECTED | N3: B/F | O3: FEES | P3: TOTAL | Q3: BALANCE | R3: EXPECTED
A4: SHANICE JEPKORIR | B4: 0256 | C4: D | E4: 10000 | F4: =E4 -> 10000 | G4: =H4+D4-F4 -> -500 | H4: 9500 | I4: =G4 -> -500 | J4: 3500 | K4: =J4 -> 3500 | L4: =M4+G4-K4 -> 0 | M4: 4000 | N4: =L4 -> 0 | P4: =O4 -> 0 | Q4: =R4+N4-P4 -> 2000 | R4: 2000
A5: JOY JEPCHUMBA | B5: 0257 | C5: D | E5: 9500 | F5: =E5 -> 9500 | G5: =H5+D5-F5 -> 0 | H5: 9500 | I5: =G5 -> 0 | J5: 4000 | K5: =J5 -> 4000 | L5: =M5+G5-K5 -> 0 | M5: 4000 | N5: =L5 -> 0 | P5: =O5 -> 0 | Q5: =R5+N5-P5 -> 2000 | R5: 2000
A6: GIFT KIPRUTO | B6: 0258 | C6: D | E6: 9500 | F6: =E6 -> 9500 | G6: =H6+D6-F6 -> 0 | H6: 9500 | I6: =G6 -> 0 | J6: 4000 | K6: =J6 -> 4000 | L6: =M6+G6-K6 -> 0 | M6: 4000 | N6: =L6 -> 0 | O6: 2000 | P6: =O6 -> 2000 | Q6: =R6+N6-P6 -> 0 | R6: 2000
A7: GIFT KIPCHUMBA | B7: 0259 | C7: D | E7: 9500 | F7: =E7 -> 9500 | G7: =H7+D7-F7 -> 0 | H7: 9500 | I7: =G7 -> 0 | J7: 4000 | K7: =J7 -> 4000 | L7: =M7+G7-K7 -> 0 | M7: 4000 | N7: =L7 -> 0 | P7: =O7 -> 0 | Q7: =R7+N7-P7 -> 2000 | R7: 2000
A8: GADDIEL KIPROTICH | B8: 0261 | C8: D | D8: 5000 | F8: =E8 -> 0 | G8: =H8+D8-F8 -> 14500 | H8: 9500 | I8: =G8 -> 14500 | K8: =J8 -> 0 | L8: =M8+G8-K8 -> 14500 | M8: 0 | N8: =L8 -> 14500 | P8: =O8 -> 0 | Q8: =R8+N8-P8 -> 14500 | R8: 0
A9: DAWID KIPKOECH | B9: 0262 | C9: D | D9: 50 | E9: 14050 | F9: =E9 -> 14050 | G9: =H9+D9-F9 -> -4500 | H9: 9500 | I9: =G9 -> -4500 | K9: =J9 -> 0 | L9: =M9+G9-K9 -> -500 | M9: 4000 | N9: =L9 -> -500 | P9: =O9 -> 0 | Q9: =R9+N9-P9 -> 1500 | R9: 2000
A10: SHERYL JEROTICH | B10: 0263 | C10: D | D10: 5000 | E10: 2000 | F10: =E10 -> 2000 | G10: =H10+D10-F10 -> 9650 | H10: 6650 | I10: =G10 -> 9650 | J10: 3000 | K10: =J10 -> 3000 | L10: =M10+G10-K10 -> 9450 | M10: 2800 | N10: =L10 -> 9450 | P10: =O10 -> 0 | Q10: =R10+N10-P10 -> 11450 | R10: 2000
A11: BRAYDEN KEMBOI | B11: 0264 | C11: D | E11: 8000 | F11: =E11 -> 8000 | G11: =H11+D11-F11 -> -1350 | H11: 6650 | I11: =G11 -> -1350 | K11: =J11 -> 0 | L11: =M11+G11-K11 -> 1450 | M11: 2800 | N11: =L11 -> 1450 | P11: =O11 -> 0 | Q11: =R11+N11-P11 -> 3450 | R11: 2000
A12: LEROY KIGEN | B12: 0265 | C12: D | E12: 9450 | F12: =E12 -> 9450 | G12: =H12+D12-F12 -> 50 | H12: 9500 | I12: =G12 -> 50 | J12: 4050 | K12: =J12 -> 4050 | L12: =M12+G12-K12 -> 0 | M12: 4000 | N12: =L12 -> 0 | P12: =O12 -> 0 | Q12: =R12+N12-P12 -> 2000 | R12: 2000
A13: JAYDEN KIPKOECH | B13: 0266 | C13: D | E13: 9000 | F13: =E13 -> 9000 | G13: =H13+D13-F13 -> 500 | H13: 9500 | I13: =G13 -> 500 | J13: 4500 | K13: =J13 -> 4500 | L13: =M13+G13-K13 -> 0 | M13: 4000 | N13: =L13 -> 0 | O13: 1000 | P13: =O13 -> 1000 | Q13: =R13+N13-P13 -> 1000 | R13: 2000
A14: PURITY CHEROTICH | B14: 0267 | C14: D | E14: 2000 | F14: =E14 -> 2000 | G14: =H14+D14-F14 -> 4650 | H14: 6650 | I14: =G14 -> 4650 | J14: 4500 | K14: =J14 -> 4500 | L14: =M14+G14-K14 -> 2950 | M14: 2800 | N14: =L14 -> 2950 | O14: 2000 | P14: =O14 -> 2000 | Q14: =R14+N14-P14 -> 2350 | R14: 1400
A15: KATHLEEN KEZIAH | B15: 0268 | C15: D | E15: 9500 | F15: =E15 -> 9500 | G15: =H15+D15-F15 -> 0 | H15: 9500 | I15: =G15 -> 0 | J15: 4000 | K15: =J15 -> 4000 | L15: =M15+G15-K15 -> 0 | M15: 4000 | N15: =L15 -> 0 | O15: 2000 | P15: =O15 -> 2000 | Q15: =R15+N15-P15 -> 0 | R15: 2000
A16: BRAVIN KIGEN | B16: 0269 | C16: D | E16: 9500 | F16: =E16 -> 9500 | G16: =H16+D16-F16 -> 0 | H16: 9500 | I16: =G16 -> 0 | J16: 2950 | K16: =J16 -> 2950 | L16: =M16+G16-K16 -> 1050 | M16: 4000 | N16: =L16 -> 1050 | P16: =O16 -> 0 | Q16: =R16+N16-P16 -> 3050 | R16: 2000
A17: BEN KIBET | B17: 0270 | C17: D | E17: 9500 | F17: =E17 -> 9500 | G17: =H17+D17-F17 -> 0 | H17: 9500 | I17: =G17 -> 0 | J17: =2250+1000 -> 3250 | K17: =J17 -> 3250 | L17: =M17+G17-K17 -> 750 | M17: 4000 | N17: =L17 -> 750 | O17: 2750 | P17: =O17 -> 2750 | Q17: =R17+N17-P17 -> 0 | R17: 2000
A18: ALLAN KIBET | B18: 0271 | C18: D | E18: 7000 | F18: =E18 -> 7000 | G18: =H18+D18-F18 -> 2500 | H18: 9500 | I18: =G18 -> 2500 | J18: 5500 | K18: =J18 -> 5500 | L18: =M18+G18-K18 -> 1000 | M18: 4000 | N18: =L18 -> 1000 | P18: =O18 -> 0 | Q18: =R18+N18-P18 -> 3000 | R18: 2000
A19: LENICE JEPKURUI | B19: 0272 | C19: D | E19: 3500 | F19: =E19 -> 3500 | G19: =H19+D19-F19 -> 6000 | H19: 9500 | I19: =G19 -> 6000 | J19: 10000 | K19: =J19 -> 10000 | L19: =M19+G19-K19 -> 0 | M19: 4000 | N19: =L19 -> 0 | P19: =O19 -> 0 | Q19: =R19+N19-P19 -> 2000 | R19: 2000
A20: LEON KIPCHIRCHIR | B20: 0273 | C20: D | E20: 8500 | F20: =E20 -> 8500 | G20: =H20+D20-F20 -> 1000 | H20: 9500 | I20: =G20 -> 1000 | J20: 5000 | K20: =J20 -> 5000 | L20: =M20+G20-K20 -> 0 | M20: 4000 | N20: =L20 -> 0 | O20: 250 | P20: =O20 -> 250 | Q20: =R20+N20-P20 -> 1750 | R20: 2000
A21: SHERYL JEBET | B21: 0274 | C21: D | E21: 9500 | F21: =E21 -> 9500 | G21: =H21+D21-F21 -> 0 | H21: 9500 | I21: =G21 -> 0 | J21: 4000 | K21: =J21 -> 4000 | L21: =M21+G21-K21 -> 0 | M21: 4000 | N21: =L21 -> 0 | O21: 2000 | P21: =O21 -> 2000 | Q21: =R21+N21-P21 -> 0 | R21: 2000
A22: BRAVIN KIPKEMBOI | B22: 0275 | C22: D | D22: -1000 | E22: 7000 | F22: =E22 -> 7000 | G22: =H22+D22-F22 -> 1500 | H22: 9500 | I22: =G22 -> 1500 | J22: 5000 | K22: =J22 -> 5000 | L22: =M22+G22-K22 -> 500 | M22: 4000 | N22: =L22 -> 500 | P22: =O22 -> 0 | Q22: =R22+N22-P22 -> 2500 | R22: 2000
A23: LIANNAH JEPCHUMBA | B23: 0276 | C23: D | E23: 9500 | F23: =E23 -> 9500 | G23: =H23+D23-F23 -> 0 | H23: 9500 | I23: =G23 -> 0 | J23: 4000 | K23: =J23 -> 4000 | L23: =M23+G23-K23 -> 0 | M23: 4000 | N23: =L23 -> 0 | O23: 1000 | P23: =O23 -> 1000 | Q23: =R23+N23-P23 -> 1000 | R23: 2000
A24: LINCOLN KIPLIMO | B24: 0277 | C24: D | E24: 3950 | F24: =E24 -> 3950 | G24: =H24+D24-F24 -> 5550 | H24: 9500 | I24: =G24 -> 5550 | J24: =4000+2000 -> 6000 | K24: =J24 -> 6000 | L24: =M24+G24-K24 -> 3550 | M24: 4000 | N24: =L24 -> 3550 | P24: =O24 -> 0 | Q24: =R24+N24-P24 -> 5550 | R24: 2000
A25: MILAN KIMUTAI | B25: 0278 | C25: D | D25: 3550 | F25: =E25 -> 0 | G25: =H25+D25-F25 -> 13050 | H25: 9500 | I25: =G25 -> 13050 | K25: =J25 -> 0 | L25: =M25+G25-K25 -> 13050 | M25: 0 | N25: =L25 -> 13050 | P25: =O25 -> 0 | Q25: =R25+N25-P25 -> 13050 | R25: 0
A26: MELVIN JEPKOGEI | B26: 0279 | C26: D | E26: 3650 | F26: =E26 -> 3650 | G26: =H26+D26-F26 -> 5850 | H26: 9500 | I26: =G26 -> 5850 | J26: =4000+1200 -> 5200 | K26: =J26 -> 5200 | L26: =M26+G26-K26 -> 4650 | M26: 4000 | N26: =L26 -> 4650 | P26: =O26 -> 0 | Q26: =R26+N26-P26 -> 6650 | R26: 2000
A27: ADRIAN KIPLIMO | B27: 0280 | C27: D | E27: 9200 | F27: =E27 -> 9200 | G27: =H27+D27-F27 -> 300 | H27: 9500 | I27: =G27 -> 300 | J27: =1000+2000 -> 3000 | K27: =J27 -> 3000 | L27: =M27+G27-K27 -> 1300 | M27: 4000 | N27: =L27 -> 1300 | P27: =O27 -> 0 | Q27: =R27+N27-P27 -> 3300 | R27: 2000
A28: IVAANAH JEROTICH | B28: 0281 | C28: D | E28: 7000 | F28: =E28 -> 7000 | G28: =H28+D28-F28 -> 2500 | H28: 9500 | I28: =G28 -> 2500 | J28: 8500 | K28: =J28 -> 8500 | L28: =M28+G28-K28 -> -2000 | M28: 4000 | N28: =L28 -> -2000 | P28: =O28 -> 0 | Q28: =R28+N28-P28 -> 0 | R28: 2000
A29: TIM KIRWA | B29: 0282 | C29: D | E29: 9500 | F29: =E29 -> 9500 | G29: =H29+D29-F29 -> 0 | H29: 9500 | I29: =G29 -> 0 | J29: 4000 | K29: =J29 -> 4000 | L29: =M29+G29-K29 -> 0 | M29: 4000 | N29: =L29 -> 0 | P29: =O29 -> 0 | Q29: =R29+N29-P29 -> 2000 | R29: 2000
A30: TIFFANY CHEBET | B30: 0283 | C30: D | E30: 9500 | F30: =E30 -> 9500 | G30: =H30+D30-F30 -> 0 | H30: 9500 | I30: =G30 -> 0 | J30: 4100 | K30: =J30 -> 4100 | L30: =M30+G30-K30 -> -100 | M30: 4000 | N30: =L30 -> -100 | P30: =O30 -> 0 | Q30: =R30+N30-P30 -> 1900 | R30: 2000
A31: CAREN JEROP | B31: 0284 | C31: D | E31: 6500 | F31: =E31 -> 6500 | G31: =H31+D31-F31 -> 3000 | H31: 9500 | I31: =G31 -> 3000 | J31: 5000 | K31: =J31 -> 5000 | L31: =M31+G31-K31 -> 2000 | M31: 4000 | N31: =L31 -> 2000 | O31: 3150 | P31: =O31 -> 3150 | Q31: =R31+N31-P31 -> 850 | R31: 2000
A32: SHANNICE JEPCHUMBA | B32: 0285 | C32: D | E32: 8000 | F32: =E32 -> 8000 | G32: =H32+D32-F32 -> 1500 | H32: 9500 | I32: =G32 -> 1500 | J32: 5500 | K32: =J32 -> 5500 | L32: =M32+G32-K32 -> 0 | M32: 4000 | N32: =L32 -> 0 | P32: =O32 -> 0 | Q32: =R32+N32-P32 -> 2000 | R32: 2000
A33: ANGEL JEROP | B33: 0286 | C33: D | E33: 14000 | F33: =E33 -> 14000 | G33: =H33+D33-F33 -> -4500 | H33: 9500 | I33: =G33 -> -4500 | J33: 550 | K33: =J33 -> 550 | L33: =M33+G33-K33 -> -1050 | M33: 4000 | N33: =L33 -> -1050 | P33: =O33 -> 0 | Q33: =R33+N33-P33 -> 950 | R33: 2000
A34: ASHLYNNE JEPCHUMBA | B34: 0287 | C34: D | D34: 4700 | E34: 9500 | F34: =E34 -> 9500 | G34: =H34+D34-F34 -> 4700 | H34: 9500 | I34: =G34 -> 4700 | K34: =J34 -> 0 | L34: =M34+G34-K34 -> 8700 | M34: 4000 | N34: =L34 -> 8700 | P34: =O34 -> 0 | Q34: =R34+N34-P34 -> 10700 | R34: 2000
A35: DERRICK KIMUTAI | B35: 0288 | C35: D | F35: =E35 -> 0 | G35: =H35+D35-F35 -> 9500 | H35: 9500 | I35: =G35 -> 9500 | K35: =J35 -> 0 | L35: =M35+G35-K35 -> 9500 | M35: 0 | N35: =L35 -> 9500 | P35: =O35 -> 0 | Q35: =R35+N35-P35 -> 9500 | R35: 0
A36: SHANIZ JEPTOO | B36: 0289 | C36: D | D36: 10500 | E36: 3800 | F36: =E36 -> 3800 | G36: =H36+D36-F36 -> 16200 | H36: 9500 | I36: =G36 -> 16200 | K36: =J36 -> 0 | L36: =M36+G36-K36 -> 20200 | M36: 4000 | N36: =L36 -> 20200 | P36: =O36 -> 0 | Q36: =R36+N36-P36 -> 20200 | R36: 0
A37: MITCHELLE JEPCHIRCHIR | B37: 0290 | C37: D | E37: 9500 | F37: =E37 -> 9500 | G37: =H37+D37-F37 -> 0 | H37: 9500 | I37: =G37 -> 0 | J37: 3000 | K37: =J37 -> 3000 | L37: =M37+G37-K37 -> 1000 | M37: 4000 | N37: =L37 -> 1000 | O37: 2000 | P37: =O37 -> 2000 | Q37: =R37+N37-P37 -> 1000 | R37: 2000
A38: DYLAN CHELUGET | B38: 0291 | C38: D | F38: =E38 -> 0 | G38: =H38+D38-F38 -> 9500 | H38: 9500 | I38: =G38 -> 9500 | K38: =J38 -> 0 | L38: =M38+G38-K38 -> 9500 | M38: 0 | N38: =L38 -> 9500 | P38: =O38 -> 0 | Q38: =R38+N38-P38 -> 9500 | R38: 0
A39: CYPRIAN KIPROP | B39: 0292 | C39: D | E39: 9500 | F39: =E39 -> 9500 | G39: =H39+D39-F39 -> 0 | H39: 9500 | I39: =G39 -> 0 | J39: =550+2450 -> 3000 | K39: =J39 -> 3000 | L39: =M39+G39-K39 -> 1000 | M39: 4000 | N39: =L39 -> 1000 | P39: =O39 -> 0 | Q39: =R39+N39-P39 -> 3000 | R39: 2000
A40: HAZEL JEPTOO | B40: 0293 | C40: D | E40: 9500 | F40: =E40 -> 9500 | G40: =H40+D40-F40 -> 0 | H40: 9500 | I40: =G40 -> 0 | J40: 3650 | K40: =J40 -> 3650 | L40: =M40+G40-K40 -> 350 | M40: 4000 | N40: =L40 -> 350 | P40: =O40 -> 0 | Q40: =R40+N40-P40 -> 2350 | R40: 2000
A41: ELVIS KIPLIMO | B41: 0294 | C41: D | E41: 9500 | F41: =E41 -> 9500 | G41: =H41+D41-F41 -> 0 | H41: 9500 | I41: =G41 -> 0 | J41: 4000 | K41: =J41 -> 4000 | L41: =M41+G41-K41 -> 0 | M41: 4000 | N41: =L41 -> 0 | O41: 2000 | P41: =O41 -> 2000 | Q41: =R41+N41-P41 -> 0 | R41: 2000
...

Sheet GRADE 1
A2: NAME OF LEARNERS | F2: 1ST TERM | L2: 2ND TERM | Q2: 3RD TERM | S2: TOTAL | T2: BALANCE | U2: EXPECTED
B3: ADM | C3: B/D | D3: B/F | E3: FEES | F3: TOTAL | G3: BALANCE | H3: EXPECTED | I3: B/F | J3: FEES | K3: TOTAL | L3: BALANCE | M3: EXPECTED | N3: B/F | O3: FEES | P3: TOTAL | Q3: BALANCE | R3: EXPECTED
A4: STACY JEBIWOTT | B4: 0231 | C4: D | E4: 11500 | F4: =E4 -> 11500 | G4: =H4+D4-F4 -> 0 | H4: 11500 | I4: =G4 -> 0 | J4: 4000 | K4: =J4 -> 4000 | L4: =M4+I4-K4 -> 0 | M4: 4000 | N4: =L4 -> 0 | P4: =O4 -> 0 | Q4: =R4+N4-P4 -> 2000 | R4: 2000
A5: JAYSON KIPKEMBOI | B5: 0232 | C5: D | D5: 8500 | F5: =E5 -> 0 | G5: =H5+D5-F5 -> 20000 | H5: 11500 | I5: =G5 -> 20000 | K5: =J5 -> 0 | L5: =M5+I5-K5 -> 20000 | M5: 0 | N5: =L5 -> 20000 | P5: =O5 -> 0 | Q5: =R5+N5-P5 -> 20000 | R5: 0
A6: DYLAN KIMUTAI | B6: 0233 | C6: D | E6: 11500 | F6: =E6 -> 11500 | G6: =H6+D6-F6 -> 0 | H6: 11500 | I6: =G6 -> 0 | J6: 4000 | K6: =J6 -> 4000 | L6: =M6+I6-K6 -> 0 | M6: 4000 | N6: =L6 -> 0 | O6: 2000 | P6: =O6 -> 2000 | Q6: =R6+N6-P6 -> 0 | R6: 2000
A7: MARLIN KIPCHUMBA | B7: 0234 | C7: D | E7: 6650 | F7: =E7 -> 6650 | G7: =H7+D7-F7 -> 4850 | H7: 11500 | I7: =G7 -> 4850 | J7: 8850 | K7: =J7 -> 8850 | L7: =M7+I7-K7 -> 0 | M7: 4000 | N7: =L7 -> 0 | O7: 2000 | P7: =O7 -> 2000 | Q7: =R7+N7-P7 -> 0 | R7: 2000
A8: DANIELLA JEPKORIR | B8: 0235 | C8: D | E8: 11500 | F8: =E8 -> 11500 | G8: =H8+D8-F8 -> 0 | H8: 11500 | I8: =G8 -> 0 | J8: 4000 | K8: =J8 -> 4000 | L8: =M8+I8-K8 -> 0 | M8: 4000 | N8: =L8 -> 0 | P8: =O8 -> 0 | Q8: =R8+N8-P8 -> 2000 | R8: 2000
A9: JOYLEEN JEPKEMBOI | B9: 0236 | C9: D | F9: =E9 -> 0 | G9: =H9+D9-F9 -> 11500 | H9: 11500 | I9: =G9 -> 11500 | K9: =J9 -> 0 | L9: =M9+I9-K9 -> 11500 | M9: 0 | N9: =L9 -> 11500 | P9: =O9 -> 0 | Q9: =R9+N9-P9 -> 11500 | R9: 0
A10: LUVINER JEBET | B10: 0237 | C10: D | E10: 11500 | F10: =E10 -> 11500 | G10: =H10+D10-F10 -> 0 | H10: 11500 | I10: =G10 -> 0 | J10: 4000 | K10: =J10 -> 4000 | L10: =M10+I10-K10 -> 0 | M10: 4000 | N10: =L10 -> 0 | O10: 2000 | P10: =O10 -> 2000 | Q10: =R10+N10-P10 -> 0 | R10: 2000
A11: SHAPHAN KIPROP | B11: 0238 | C11: D | D11: 1000 | E11: 12500 | F11: =E11 -> 12500 | G11: =H11+D11-F11 -> 0 | H11: 11500 | I11: =G11 -> 0 | J11: 4000 | K11: =J11 -> 4000 | L11: =M11+I11-K11 -> 0 | M11: 4000 | N11: =L11 -> 0 | P11: =O11 -> 0 | Q11: =R11+N11-P11 -> 2000 | R11: 2000
A12: ABIGAEL JEPCHUMBA | B12: 0239 | C12: D | D12: 6400 | F12: =E12 -> 0 | G12: =H12+D12-F12 -> 17900 | H12: 11500 | I12: =G12 -> 17900 | K12: =J12 -> 0 | L12: =M12+I12-K12 -> 17900 | M12: 0 | N12: =L12 -> 17900 | P12: =O12 -> 0 | Q12: =R12+N12-P12 -> 17900 | R12: 0
A13: RYAN KIPROP | B13: 0240 | C13: D | E13: 7500 | F13: =E13 -> 7500 | G13: =H13+D13-F13 -> 4000 | H13: 11500 | I13: =G13 -> 4000 | K13: =J13 -> 0 | L13: =M13+I13-K13 -> 8000 | M13: 4000 | N13: =L13 -> 8000 | P13: =O13 -> 0 | Q13: =R13+N13-P13 -> 10000 | R13: 2000
A14: SHERYLINE JERONO | B14: 0241 | C14: D | E14: 10450 | F14: =E14 -> 10450 | G14: =H14+D14-F14 -> 1050 | H14: 11500 | I14: =G14 -> 1050 | J14: 5050 | K14: =J14 -> 5050 | L14: =M14+I14-K14 -> 0 | M14: 4000 | N14: =L14 -> 0 | O14: 2000 | P14: =O14 -> 2000 | Q14: =R14+N14-P14 -> 0 | R14: 2000
A15: DAISY JEROTICH | B15: 0242 | C15: D | D15: 5175 | F15: =E15 -> 0 | G15: =H15+D15-F15 -> 16675 | H15: 11500 | I15: =G15 -> 16675 | K15: =J15 -> 0 | L15: =M15+I15-K15 -> 16675 | M15: 0 | N15: =L15 -> 16675 | P15: =O15 -> 0 | Q15: =R15+N15-P15 -> 16675 | R15: 0
A16: ASHLEY JERUTO | B16: 0243 | C16: D | D16: 7500 | F16: =E16 -> 0 | G16: =H16+D16-F16 -> 19000 | H16: 11500 | I16: =G16 -> 19000 | K16: =J16 -> 0 | L16: =M16+I16-K16 -> 19000 | M16: 0 | N16: =L16 -> 19000 | P16: =O16 -> 0 | Q16: =R16+N16-P16 -> 19000 | R16: 0
A17: PRECIOUS JEPTOO | B17: 0244 | C17: D | E17: 9500 | F17: =E17 -> 9500 | G17: =H17+D17-F17 -> 2000 | H17: 11500 | I17: =G17 -> 2000 | J17: 6000 | K17: =J17 -> 6000 | L17: =M17+I17-K17 -> 0 | M17: 4000 | N17: =L17 -> 0 | P17: =O17 -> 0 | Q17: =R17+N17-P17 -> 2000 | R17: 2000
A18: SHANTEL JEPKOGEI | B18: 0245 | C18: D | E18: 11500 | F18: =E18 -> 11500 | G18: =H18+D18-F18 -> 0 | H18: 11500 | I18: =G18 -> 0 | J18: 4000 | K18: =J18 -> 4000 | L18: =M18+I18-K18 -> 0 | M18: 4000 | N18: =L18 -> 0 | O18: 1000 | P18: =O18 -> 1000 | Q18: =R18+N18-P18 -> 1000 | R18: 2000
A19: TIFANNIE DEBORAH | B19: 0246 | C19: D | E19: 15500 | F19: =E19 -> 15500 | G19: =H19+D19-F19 -> -4000 | H19: 11500 | I19: =G19 -> -4000 | J19: 2000 | K19: =J19 -> 2000 | L19: =M19+I19-K19 -> -2000 | M19: 4000 | N19: =L19 -> -2000 | P19: =O19 -> 0 | Q19: =R19+N19-P19 -> 0 | R19: 2000
A20: LAYLA CHEBET | B20: 0247 | C20: D | E20: 11500 | F20: =E20 -> 11500 | G20: =H20+D20-F20 -> 0 | H20: 11500 | I20: =G20 -> 0 | J20: 4000 | K20: =J20 -> 4000 | L20: =M20+I20-K20 -> 0 | M20: 4000 | N20: =L20 -> 0 | O20: 2000 | P20: =O20 -> 2000 | Q20: =R20+N20-P20 -> 0 | R20: 2000
A21: ETHAN KIMUTAI | B21: 0248 | C21: D | E21: 10450 | F21: =E21 -> 10450 | G21: =H21+D21-F21 -> 1050 | H21: 11500 | I21: =G21 -> 1050 | J21: 5050 | K21: =J21 -> 5050 | L21: =M21+I21-K21 -> 0 | M21: 4000 | N21: =L21 -> 0 | O21: 1000 | P21: =O21 -> 1000 | Q21: =R21+N21-P21 -> 1000 | R21: 2000
A22: BRITTNEY LEAH KEMBOI | B22: 0249 | C22: D | D22: 2000 | E22: 13500 | F22: =E22 -> 13500 | G22: =H22+D22-F22 -> 0 | H22: 11500 | I22: =G22 -> 0 | J22: 4000 | K22: =J22 -> 4000 | L22: =M22+I22-K22 -> 0 | M22: 4000 | N22: =L22 -> 0 | O22: 2000 | P22: =O22 -> 2000 | Q22: =R22+N22-P22 -> 0 | R22: 2000
A23: CAREN JEBET | B23: 0250 | C23: D | E23: 9850 | F23: =E23 -> 9850 | G23: =H23+D23-F23 -> 1650 | H23: 11500 | I23: =G23 -> 1650 | J23: 5650 | K23: =J23 -> 5650 | L23: =M23+I23-K23 -> 0 | M23: 4000 | N23: =L23 -> 0 | O23: 2000 | P23: =O23 -> 2000 | Q23: =R23+N23-P23 -> 0 | R23: 2000
A24: NICOLE CHIRCHIR | B24: 0251 | C24: D | E24: 11500 | F24: =E24 -> 11500 | G24: =H24+D24-F24 -> 0 | H24: 11500 | I24: =G24 -> 0 | J24: 4000 | K24: =J24 -> 4000 | L24: =M24+I24-K24 -> 0 | M24: 4000 | N24: =L24 -> 0 | O24: 2000 | P24: =O24 -> 2000 | Q24: =R24+N24-P24 -> 0 | R24: 2000
A25: ABIGAEL JELAGAT | B25: 0252 | C25: D | E25: 11500 | F25: =E25 -> 11500 | G25: =H25+D25-F25 -> 0 | H25: 11500 | I25: =G25 -> 0 | J25: 4000 | K25: =J25 -> 4000 | L25: =M25+I25-K25 -> 0 | M25: 4000 | N25: =L25 -> 0 | P25: =O25 -> 0 | Q25: =R25+N25-P25 -> 2000 | R25: 2000
A26: NATASHA JEBET BUSIENEI | B26: 0253 | C26: D | E26: 11500 | F26: =E26 -> 11500 | G26: =H26+D26-F26 -> 0 | H26: 11500 | I26: =G26 -> 0 | J26: 4000 | K26: =J26 -> 4000 | L26: =M26+I26-K26 -> 0 | M26: 4000 | N26: =L26 -> 0 | O26: 2000 | P26: =O26 -> 2000 | Q26: =R26+N26-P26 -> 0 | R26: 2000
A27: VINCENT KIPKEMBOI | B27: 0254 | C27: D | E27: 10700 | F27: =E27 -> 10700 | G27: =H27+D27-F27 -> 800 | H27: 11500 | I27: =G27 -> 800 | J27: 4800 | K27: =J27 -> 4800 | L27: =M27+I27-K27 -> 0 | M27: 4000 | N27: =L27 -> 0 | P27: =O27 -> 0 | Q27: =R27+N27-P27 -> 2000 | R27: 2000
A28: BLESSING JEMUTAI | B28: 0255 | C28: D | E28: 7000 | F28: =E28 -> 7000 | G28: =H28+D28-F28 -> 4500 | H28: 11500 | I28: =G28 -> 4500 | J28: 3000 | K28: =J28 -> 3000 | L28: =M28+I28-K28 -> 5500 | M28: 4000 | N28: =L28 -> 5500 | P28: =O28 -> 0 | Q28: =R28+N28-P28 -> 7500 | R28: 2000
A29: ALVIN KIPCHIRCHIR | B29: 0344 | C29: D | E29: 11500 | F29: =E29 -> 11500 | G29: =H29+D29-F29 -> 0 | H29: 11500 | I29: =G29 -> 0 | J29: 4000 | K29: =J29 -> 4000 | L29: =M29+I29-K29 -> 0 | M29: 4000 | N29: =L29 -> 0 | O29: 1150 | P29: =O29 -> 1150 | Q29: =R29+N29-P29 -> 850 | R29: 2000
A30: PRINCE LIAM KIPKOGEI | B30: 0345 | C30: D | E30: 10000 | F30: =E30 -> 10000 | G30: =H30+D30-F30 -> 1500 | H30: 11500 | I30: =G30 -> 1500 | J30: 5500 | K30: =J30 -> 5500 | L30: =M30+I30-K30 -> 0 | M30: 4000 | N30: =L30 -> 0 | P30: =O30 -> 0 | Q30: =R30+N30-P30 -> 2000 | R30: 2000
A31: VANISHA JEPTOO | B31: 0378 | C31: D | E31: 11500 | F31: =E31 -> 11500 | G31: =H31+D31-F31 -> 0 | H31: 11500 | I31: =G31 -> 0 | J31: 4000 | K31: =J31 -> 4000 | L31: =M31+I31-K31 -> 0 | M31: 4000 | N31: =L31 -> 0 | O31: 1000 | P31: =O31 -> 1000 | Q31: =R31+N31-P31 -> 1000 | R31: 2000
A32: EDDY KIPTOO | B32: 0334 | C32: D | E32: 6000 | F32: =E32 -> 6000 | G32: =H32+D32-F32 -> 5500 | H32: 11500 | I32: =G32 -> 5500 | J32: 9000 | K32: =J32 -> 9000 | L32: =M32+I32-K32 -> 500 | M32: 4000 | N32: =L32 -> 500 | O32: 2500 | P32: =O32 -> 2500 | Q32: =R32+N32-P32 -> 0 | R32: 2000
A33: ELIEZEAR KOECH | B33: 0328 | C33: D | E33: 11500 | F33: =E33 -> 11500 | G33: =H33+D33-F33 -> 0 | H33: 11500 | I33: =G33 -> 0 | J33: 4000 | K33: =J33 -> 4000 | L33: =M33+I33-K33 -> 0 | M33: 4000 | N33: =L33 -> 0 | P33: =O33 -> 0 | Q33: =R33+N33-P33 -> 2000 | R33: 2000
A34: GIDEON KIBET KOECH | B34: 0341 | C34: D | E34: 11500 | F34: =E34 -> 11500 | G34: =H34+D34-F34 -> 0 | H34: 11500 | I34: =G34 -> 0 | J34: 4000 | K34: =J34 -> 4000 | L34: =M34+I34-K34 -> 0 | M34: 4000 | N34: =L34 -> 0 | P34: =O34 -> 0 | Q34: =R34+N34-P34 -> 2000 | R34: 2000
A35: DORAH CHEROTICH | B35: 0352 | C35: D | E35: 11500 | F35: =E35 -> 11500 | G35: =H35+D35-F35 -> 0 | H35: 11500 | I35: =G35 -> 0 | J35: 4000 | K35: =J35 -> 4000 | L35: =M35+I35-K35 -> 0 | M35: 4000 | N35: =L35 -> 0 | O35: 2000 | P35: =O35 -> 2000 | Q35: =R35+N35-P35 -> 0 | R35: 2000
A36: EDEN KIMUTAI | B36: 0368 | C36: D | E36: 8000 | F36: =E36 -> 8000 | G36: =H36+D36-F36 -> 3500 | H36: 11500 | I36: =G36 -> 3500 | J36: 7500 | K36: =J36 -> 7500 | L36: =M36+I36-K36 -> 0 | M36: 4000 | N36: =L36 -> 0 | O36: 1200 | P36: =O36 -> 1200 | Q36: =R36+N36-P36 -> 800 | R36: 2000
A37: BRAVIN KIPKOECH TUM | B37: 0373 | C37: D | E37: 10950 | F37: =E37 -> 10950 | G37: =H37+D37-F37 -> 550 | H37: 11500 | I37: =G37 -> 550 | J37: 4550 | K37: =J37 -> 4550 | L37: =M37+I37-K37 -> 0 | M37: 4000 | N37: =L37 -> 0 | O37: 2000 | P37: =O37 -> 2000 | Q37: =R37+N37-P37 -> 0 | R37: 2000
A38: LOVISA IRIS NATO | B38: 0384 | C38: D | E38: 7500 | F38: =E38 -> 7500 | G38: =H38+D38-F38 -> 4000 | H38: 11500 | I38: =G38 -> 4000 | K38: =J38 -> 0 | L38: =M38+I38-K38 -> 4000 | M38: 0 | N38: =L38 -> 4000 | P38: =O38 -> 0 | Q38: =R38+N38-P38 -> 6000 | R38: 2000
A39: BRENDA CHEPCHUMBA | B39: 0389 | C39: D | E39: 11500 | F39: =E39 -> 11500 | G39: =H39+D39-F39 -> 0 | H39: 11500 | I39: =G39 -> 0 | J39: 4000 | K39: =J39 -> 4000 | L39: =M39+I39-K39 -> 0 | M39: 4000 | N39: =L39 -> 0 | P39: =O39 -> 0 | Q39: =R39+N39-P39 -> 2000 | R39: 2000
A40: BRIGHTON KIPRUTO | B40: 0415 | C40: D | E40: 11500 | F40: =E40 -> 11500 | G40: =H40+D40-F40 -> 0 | H40: 11500 | I40: =G40 -> 0 | J40: =3000+1000 -> 4000 | K40: =J40 -> 4000 | L40: =M40+I40-K40 -> 0 | M40: 4000 | N40: =L40 -> 0 | P40: =O40 -> 0 | Q40: =R40+N40-P40 -> 2000 | R40: 2000
A41: BLESSING CHEROP | B41: 0416 | C41: D | E41: 10400 | F41: =E41 -> 10400 | G41: =H41+D41-F41 -> 1100 | H41: 11500 | I41: =G41 -> 1100 | J41: =5050+50 -> 5100 | K41: =J41 -> 5100 | L41: =M41+I41-K41 -> 0 | M41: 4000 | N41: =L41 -> 0 | P41: =O41 -> 0 | Q41: =R41+N41-P41 -> 2000 | R41: 2000
...

Sheet GRADE 2
F2: 1ST TERM | L2: 2ND TERM | Q2: 3RD TERM | S2: TOTAL | T2: BALANCE | U2: EXPECTED
A3: NAME OF LEARNER | B3: ADM | C3: B/D | D3: B/F | E3: FEES | F3: TOTAL | G3: BALANCE | H3: EXPECTED | I3: B/F | J3: FEES | K3: TOTAL | L3: BALANCE | M3: EXPECTED | N3: B/F | O3: FEES | P3: TOTAL | Q3: BALANCE | R3: EXPECTED
A4: BRAVE KIPRONO | B4: 0186 | C4: D | E4: 11500 | F4: =E4 -> 11500 | G4: =H4+D4-F4 -> 0 | H4: 11500 | I4: =G4 -> 0 | J4: 4000 | K4: =J4 -> 4000 | L4: =M4+I4-K4 -> 0 | M4: 4000 | N4: =L4 -> 0 | P4: =O4 -> 0 | Q4: =R4+N4-P4 -> 2000 | R4: 2000
A5: BILLY KIPCHIRCHIR | B5: 0187 | C5: D | E5: 5000 | F5: =E5 -> 5000 | G5: =H5+D5-F5 -> 6500 | H5: 11500 | I5: =G5 -> 6500 | J5: 9500 | K5: =J5 -> 9500 | L5: =M5+I5-K5 -> 1000 | M5: 4000 | N5: =L5 -> 1000 | O5: 3000 | P5: =O5 -> 3000 | Q5: =R5+N5-P5 -> 0 | R5: 2000
A6: SHERYL JEBET | B6: 0188 | C6: D | E6: 11500 | F6: =E6 -> 11500 | G6: =H6+D6-F6 -> 0 | H6: 11500 | I6: =G6 -> 0 | J6: 4000 | K6: =J6 -> 4000 | L6: =M6+I6-K6 -> 0 | M6: 4000 | N6: =L6 -> 0 | O6: 1000 | P6: =O6 -> 1000 | Q6: =R6+N6-P6 -> 1000 | R6: 2000
A7: FAITH JEPKEMBOI | B7: 0189 | C7: D | E7: 11000 | F7: =E7 -> 11000 | G7: =H7+D7-F7 -> 500 | H7: 11500 | I7: =G7 -> 500 | J7: 4500 | K7: =J7 -> 4500 | L7: =M7+I7-K7 -> 0 | M7: 4000 | N7: =L7 -> 0 | P7: =O7 -> 0 | Q7: =R7+N7-P7 -> 2000 | R7: 2000
A8: SHANTEL JEPKOECH | B8: 0190 | C8: D | E8: 11500 | F8: =E8 -> 11500 | G8: =H8+D8-F8 -> 0 | H8: 11500 | I8: =G8 -> 0 | J8: 4000 | K8: =J8 -> 4000 | L8: =M8+I8-K8 -> 0 | M8: 4000 | N8: =L8 -> 0 | P8: =O8 -> 0 | Q8: =R8+N8-P8 -> 2000 | R8: 2000
A9: DEBORAH JEPCHUMBA | B9: 0191 | C9: D | E9: 11500 | F9: =E9 -> 11500 | G9: =H9+D9-F9 -> 0 | H9: 11500 | I9: =G9 -> 0 | J9: 3000 | K9: =J9 -> 3000 | L9: =M9+I9-K9 -> 1000 | M9: 4000 | N9: =L9 -> 1000 | O9: 3000 | P9: =O9 -> 3000 | Q9: =R9+N9-P9 -> 0 | R9: 2000
A10: KEILAH JEPKOECH | B10: 0192 | C10: D | E10: 11500 | F10: =E10 -> 11500 | G10: =H10+D10-F10 -> 0 | H10: 11500 | I10: =G10 -> 0 | J10: 4000 | K10: =J10 -> 4000 | L10: =M10+I10-K10 -> 0 | M10: 4000 | N10: =L10 -> 0 | O10: 3300 | P10: =O10 -> 3300 | Q10: =R10+N10-P10 -> -1300 | R10: 2000
A11: FAITH JEPTOO | B11: 0193 | C11: D | E11: 11500 | F11: =E11 -> 11500 | G11: =H11+D11-F11 -> 0 | H11: 11500 | I11: =G11 -> 0 | J11: 4000 | K11: =J11 -> 4000 | L11: =M11+I11-K11 -> 0 | M11: 4000 | N11: =L11 -> 0 | P11: =O11 -> 0 | Q11: =R11+N11-P11 -> 2000 | R11: 2000
A12: BLESSING JEMUTAI | B12: 0194 | C12: D | F12: =E12 -> 0 | G12: =H12+D12-F12 -> 11500 | H12: 11500 | I12: =G12 -> 11500 | K12: =J12 -> 0 | L12: =M12+I12-K12 -> 11500 | M12: 0 | N12: =L12 -> 11500 | P12: =O12 -> 0 | Q12: =R12+N12-P12 -> 11500 | R12: 0
A13: BECKY JEROP | B13: 0195 | C13: D | E13: 11500 | F13: =E13 -> 11500 | G13: =H13+D13-F13 -> 0 | H13: 11500 | I13: =G13 -> 0 | J13: 6000 | K13: =J13 -> 6000 | L13: =M13+I13-K13 -> -2000 | M13: 4000 | N13: =L13 -> -2000 | P13: =O13 -> 0 | Q13: =R13+N13-P13 -> 0 | R13: 2000
A14: JAYDEN KIPCHUMBA | B14: 0196 | C14: D | E14: 6300 | F14: =E14 -> 6300 | G14: =H14+D14-F14 -> 5200 | H14: 11500 | I14: =G14 -> 5200 | J14: 9200 | K14: =J14 -> 9200 | L14: =M14+I14-K14 -> 0 | M14: 4000 | N14: =L14 -> 0 | P14: =O14 -> 0 | Q14: =R14+N14-P14 -> 2000 | R14: 2000
A15: BRAVINE KIPCHUMBA | B15: 0197 | C15: D | F15: =E15 -> 0 | G15: =H15+D15-F15 -> 11500 | H15: 11500 | I15: =G15 -> 11500 | K15: =J15 -> 0 | L15: =M15+I15-K15 -> 11500 | M15: 0 | N15: =L15 -> 11500 | P15: =O15 -> 0 | Q15: =R15+N15-P15 -> 11500 | R15: 0
A16: DENNIS KIPRONO | B16: 0198 | C16: D | E16: 15500 | F16: =E16 -> 15500 | G16: =H16+D16-F16 -> -4000 | H16: 11500 | I16: =G16 -> -4000 | K16: =J16 -> 0 | L16: =M16+I16-K16 -> 0 | M16: 4000 | N16: =L16 -> 0 | P16: =O16 -> 0 | Q16: =R16+N16-P16 -> 2000 | R16: 2000
A17: ALEXIS KIPKORIR | B17: 0199 | C17: D | D17: 1000 | E17: 5000 | F17: =E17 -> 5000 | G17: =H17+D17-F17 -> 7500 | H17: 11500 | I17: =G17 -> 7500 | J17: =2000+1000 -> 3000 | K17: =J17 -> 3000 | L17: =M17+I17-K17 -> 8500 | M17: 4000 | N17: =L17 -> 8500 | P17: =O17 -> 0 | Q17: =R17+N17-P17 -> 10500 | R17: 2000
A18: KELVIN KIPROP | B18: 0200 | C18: D | D18: 4775 | F18: =E18 -> 0 | G18: =H18+D18-F18 -> 16275 | H18: 11500 | I18: =G18 -> 16275 | K18: =J18 -> 0 | L18: =M18+I18-K18 -> 16275 | M18: 0 | N18: =L18 -> 16275 | P18: =O18 -> 0 | Q18: =R18+N18-P18 -> 16275 | R18: 0
A19: BRADLINE KIPROP | B19: 0201 | C19: D | E19: 11500 | F19: =E19 -> 11500 | G19: =H19+D19-F19 -> 0 | H19: 11500 | I19: =G19 -> 0 | J19: 4000 | K19: =J19 -> 4000 | L19: =M19+I19-K19 -> 0 | M19: 4000 | N19: =L19 -> 0 | P19: =O19 -> 0 | Q19: =R19+N19-P19 -> 2000 | R19: 2000
A20: BERYL JEPKURUI | B20: 0202 | C20: D | E20: 6000 | F20: =E20 -> 6000 | G20: =H20+D20-F20 -> 5500 | H20: 11500 | I20: =G20 -> 5500 | J20: 3000 | K20: =J20 -> 3000 | L20: =M20+I20-K20 -> 6500 | M20: 4000 | N20: =L20 -> 6500 | O20: 6000 | P20: =O20 -> 6000 | Q20: =R20+N20-P20 -> 2500 | R20: 2000
A21: BRAVINE KIPROTICH | B21: 0203 | C21: D | E21: 11500 | F21: =E21 -> 11500 | G21: =H21+D21-F21 -> 0 | H21: 11500 | I21: =G21 -> 0 | J21: 4000 | K21: =J21 -> 4000 | L21: =M21+I21-K21 -> 0 | M21: 4000 | N21: =L21 -> 0 | P21: =O21 -> 0 | Q21: =R21+N21-P21 -> 2000 | R21: 2000
A22: JOY JELANGAT | B22: 0204 | C22: D | E22: 5150 | F22: =E22 -> 5150 | G22: =H22+D22-F22 -> 6350 | H22: 11500 | I22: =G22 -> 6350 | J22: 10350 | K22: =J22 -> 10350 | L22: =M22+I22-K22 -> 0 | M22: 4000 | N22: =L22 -> 0 | P22: =O22 -> 0 | Q22: =R22+N22-P22 -> 2000 | R22: 2000
A23: RUBBY JERONO | B23: 0205 | C23: D | E23: 10650 | F23: =E23 -> 10650 | G23: =H23+D23-F23 -> 850 | H23: 11500 | I23: =G23 -> 850 | J23: 4850 | K23: =J23 -> 4850 | L23: =M23+I23-K23 -> 0 | M23: 4000 | N23: =L23 -> 0 | P23: =O23 -> 0 | Q23: =R23+N23-P23 -> 2000 | R23: 2000
A24: EVANS KIPTOO | B24: 0206 | C24: D | E24: 11150 | F24: =E24 -> 11150 | G24: =H24+D24-F24 -> 350 | H24: 11500 | I24: =G24 -> 350 | J24: 4350 | K24: =J24 -> 4350 | L24: =M24+I24-K24 -> 0 | M24: 4000 | N24: =L24 -> 0 | P24: =O24 -> 0 | Q24: =R24+N24-P24 -> 2000 | R24: 2000
A25: ELI TOO KIPRUTO | B25: 0207 | C25: D | E25: 11500 | F25: =E25 -> 11500 | G25: =H25+D25-F25 -> 0 | H25: 11500 | I25: =G25 -> 0 | J25: 4000 | K25: =J25 -> 4000 | L25: =M25+I25-K25 -> 0 | M25: 4000 | N25: =L25 -> 0 | P25: =O25 -> 0 | Q25: =R25+N25-P25 -> 2000 | R25: 2000
A26: JAPHET KIPROP | B26: 0208 | C26: D | E26: 11500 | F26: =E26 -> 11500 | G26: =H26+D26-F26 -> 0 | H26: 11500 | I26: =G26 -> 0 | J26: 4000 | K26: =J26 -> 4000 | L26: =M26+I26-K26 -> 0 | M26: 4000 | N26: =L26 -> 0 | O26: 1000 | P26: =O26 -> 1000 | Q26: =R26+N26-P26 -> 1000 | R26: 2000
A27: KYLIAN KIPNG’ENO | B27: 0209 | C27: D | E27: 11500 | F27: =E27 -> 11500 | G27: =H27+D27-F27 -> 0 | H27: 11500 | I27: =G27 -> 0 | J27: 4000 | K27: =J27 -> 4000 | L27: =M27+I27-K27 -> 0 | M27: 4000 | N27: =L27 -> 0 | P27: =O27 -> 0 | Q27: =R27+N27-P27 -> 2000 | R27: 2000
A28: ADRIAN KIPTOO | B28: 0210 | C28: D | E28: 11500 | F28: =E28 -> 11500 | G28: =H28+D28-F28 -> 0 | H28: 11500 | I28: =G28 -> 0 | J28: =3500+500 -> 4000 | K28: =J28 -> 4000 | L28: =M28+I28-K28 -> 0 | M28: 4000 | N28: =L28 -> 0 | P28: =O28 -> 0 | Q28: =R28+N28-P28 -> 2000 | R28: 2000
A29: JIBRAN KIGEN | B29: 0211 | C29: D | E29: 11500 | F29: =E29 -> 11500 | G29: =H29+D29-F29 -> 0 | H29: 11500 | I29: =G29 -> 0 | J29: 4000 | K29: =J29 -> 4000 | L29: =M29+I29-K29 -> 0 | M29: 4000 | N29: =L29 -> 0 | P29: =O29 -> 0 | Q29: =R29+N29-P29 -> 2000 | R29: 2000
A30: MITCHELLE JELIMO TANUI | B30: 0212 | C30: D | E30: 17500 | F30: =E30 -> 17500 | G30: =H30+D30-F30 -> -6000 | H30: 11500 | I30: =G30 -> -6000 | K30: =J30 -> 0 | L30: =M30+I30-K30 -> -2000 | M30: 4000 | N30: =L30 -> -2000 | P30: =O30 -> 0 | Q30: =R30+N30-P30 -> 0 | R30: 2000
A31: ABIGAEL JEROTICH | B31: 0213 | C31: D | E31: 11500 | F31: =E31 -> 11500 | G31: =H31+D31-F31 -> 0 | H31: 11500 | I31: =G31 -> 0 | J31: 4000 | K31: =J31 -> 4000 | L31: =M31+I31-K31 -> 0 | M31: 4000 | N31: =L31 -> 0 | P31: =O31 -> 0 | Q31: =R31+N31-P31 -> 2000 | R31: 2000
A32: ABIDAH JELIMO | B32: 0214 | C32: D | E32: 11500 | F32: =E32 -> 11500 | G32: =H32+D32-F32 -> 0 | H32: 11500 | I32: =G32 -> 0 | J32: 4000 | K32: =J32 -> 4000 | L32: =M32+I32-K32 -> 0 | M32: 4000 | N32: =L32 -> 0 | P32: =O32 -> 0 | Q32: =R32+N32-P32 -> 2000 | R32: 2000
A33: MAYA SOGOMO JEBET | B33: 0215 | C33: D | E33: 9650 | F33: =E33 -> 9650 | G33: =H33+D33-F33 -> 1850 | H33: 11500 | I33: =G33 -> 1850 | J33: 7650 | K33: =J33 -> 7650 | L33: =M33+I33-K33 -> -1800 | M33: 4000 | N33: =L33 -> -1800 | P33: =O33 -> 0 | Q33: =R33+N33-P33 -> 200 | R33: 2000
A34: FANUEL KIPCHIRCHIR | B34: 0216 | C34: D | E34: 10000 | F34: =E34 -> 10000 | G34: =H34+D34-F34 -> 1500 | H34: 11500 | I34: =G34 -> 1500 | J34: 5500 | K34: =J34 -> 5500 | L34: =M34+I34-K34 -> 0 | M34: 4000 | N34: =L34 -> 0 | P34: =O34 -> 0 | Q34: =R34+N34-P34 -> 2000 | R34: 2000
A35: CLAIRE JEPCHIRCHIR | B35: 0217 | C35: D | E35: 11500 | F35: =E35 -> 11500 | G35: =H35+D35-F35 -> 0 | H35: 11500 | I35: =G35 -> 0 | J35: 6000 | K35: =J35 -> 6000 | L35: =M35+I35-K35 -> -2000 | M35: 4000 | N35: =L35 -> -2000 | P35: =O35 -> 0 | Q35: =R35+N35-P35 -> 0 | R35: 2000
A36: JOY JEPKORIR | B36: 0218 | C36: D | E36: 9750 | F36: =E36 -> 9750 | G36: =H36+D36-F36 -> 1750 | H36: 11500 | I36: =G36 -> 1750 | J36: =4750+1000 -> 5750 | K36: =J36 -> 5750 | L36: =M36+I36-K36 -> 0 | M36: 4000 | N36: =L36 -> 0 | P36: =O36 -> 0 | Q36: =R36+N36-P36 -> 2000 | R36: 2000
A37: ESSY JOY JEBET | B37: 0219 | C37: D | E37: 11500 | F37: =E37 -> 11500 | G37: =H37+D37-F37 -> 0 | H37: 11500 | I37: =G37 -> 0 | J37: 4000 | K37: =J37 -> 4000 | L37: =M37+I37-K37 -> 0 | M37: 4000 | N37: =L37 -> 0 | P37: =O37 -> 0 | Q37: =R37+N37-P37 -> 2000 | R37: 2000
A38: WAYNE KIPKORIR | B38: 0220 | C38: D | E38: 10000 | F38: =E38 -> 10000 | G38: =H38+D38-F38 -> 1500 | H38: 11500 | I38: =G38 -> 1500 | J38: =3000+500 -> 3500 | K38: =J38 -> 3500 | L38: =M38+I38-K38 -> 2000 | M38: 4000 | N38: =L38 -> 2000 | P38: =O38 -> 0 | Q38: =R38+N38-P38 -> 4000 | R38: 2000
A39: BLESSING JELAGAT | B39: 0221 | C39: D | E39: 11500 | F39: =E39 -> 11500 | G39: =H39+D39-F39 -> 0 | H39: 11500 | I39: =G39 -> 0 | J39: 4000 | K39: =J39 -> 4000 | L39: =M39+I39-K39 -> 0 | M39: 4000 | N39: =L39 -> 0 | P39: =O39 -> 0 | Q39: =R39+N39-P39 -> 2000 | R39: 2000
A40: TRACY JELIMO | B40: 0222 | C40: D | D40: 2000 | E40: 11500 | F40: =E40 -> 11500 | G40: =H40+D40-F40 -> 2000 | H40: 11500 | I40: =G40 -> 2000 | K40: =J40 -> 0 | L40: =M40+I40-K40 -> 6000 | M40: 4000 | N40: =L40 -> 6000 | P40: =O40 -> 0 | Q40: =R40+N40-P40 -> 8000 | R40: 2000
A41: LEWIS LETTING | B41: 0223 | C41: D | D41: 2000 | F41: =E41 -> 0 | G41: =H41+D41-F41 -> 13500 | H41: 11500 | I41: =G41 -> 13500 | K41: =J41 -> 0 | L41: =M41+I41-K41 -> 13500 | M41: 0 | N41: =L41 -> 13500 | P41: =O41 -> 0 | Q41: =R41+N41-P41 -> 13500 | R41: 0
...

Sheet GRADE 3
A2: NAME OF LEARNER | F2: 1ST TERM | L2: 2ND TERM | Q2: 3RD TERM | S2: TOTAL | T2: BALANCE | U2: EXPECTED
B3: ADM | C3: B/D | D3: B/F | E3: FEES | F3: TOTAL | G3: BALANCE | H3: EXPECTED | I3: B/F | J3: FEES | K3: TOTAL | L3: BALANCE | M3: EXPECTED | N3: B/F | O3: FEES | P3: TOTAL | Q3: BALANCE | R3: EXPECTED
A4: SANDRAH JEPKOECH RONO | B4: 0137 | C4: D | E4: 11500 | F4: =E4 -> 11500 | G4: =H4+D4-F4 -> 0 | H4: 11500 | I4: =G4 -> 0 | J4: 4000 | K4: =J4 -> 4000 | L4: =M4+I4-K4 -> 0 | M4: 4000 | N4: =L4 -> 0 | O4: 2000 | P4: =O4 -> 2000 | Q4: =N4+R4-P4 -> 0 | R4: 2000
A5: DAVID KIPROP KOGEI | B5: 0138 | C5: D | E5: 11500 | F5: =E5 -> 11500 | G5: =H5+D5-F5 -> 0 | H5: 11500 | I5: =G5 -> 0 | J5: 4000 | K5: =J5 -> 4000 | L5: =M5+I5-K5 -> 0 | M5: 4000 | N5: =L5 -> 0 | P5: =O5 -> 0 | Q5: =N5+R5-P5 -> 2000 | R5: 2000
A6: ROY KIPRUTO KIMELI | B6: 0139 | C6: D | E6: 11500 | F6: =E6 -> 11500 | G6: =H6+D6-F6 -> 0 | H6: 11500 | I6: =G6 -> 0 | J6: 2000 | K6: =J6 -> 2000 | L6: =M6+I6-K6 -> 2000 | M6: 4000 | N6: =L6 -> 2000 | O6: 2000 | P6: =O6 -> 2000 | Q6: =N6+R6-P6 -> 2000 | R6: 2000
A7: TRACY JEROP | B7: 0140 | C7: D | E7: 5000 | F7: =E7 -> 5000 | G7: =H7+D7-F7 -> 6500 | H7: 11500 | I7: =G7 -> 6500 | J7: 9500 | K7: =J7 -> 9500 | L7: =M7+I7-K7 -> 1000 | M7: 4000 | N7: =L7 -> 1000 | O7: 3000 | P7: =O7 -> 3000 | Q7: =N7+R7-P7 -> 0 | R7: 2000
A8: BRIVIN KIBET MELLY | B8: 0141 | C8: D | E8: 10000 | F8: =E8 -> 10000 | G8: =H8+D8-F8 -> 1500 | H8: 11500 | I8: =G8 -> 1500 | J8: 4750 | K8: =J8 -> 4750 | L8: =M8+I8-K8 -> 750 | M8: 4000 | N8: =L8 -> 750 | P8: =O8 -> 0 | Q8: =N8+R8-P8 -> 2750 | R8: 2000
A9: RYAN KIMUTAI KALYA | B9: 0142 | C9: D | E9: 10150 | F9: =E9 -> 10150 | G9: =H9+D9-F9 -> 1350 | H9: 11500 | I9: =G9 -> 1350 | J9: 5350 | K9: =J9 -> 5350 | L9: =M9+I9-K9 -> 0 | M9: 4000 | N9: =L9 -> 0 | P9: =O9 -> 0 | Q9: =N9+R9-P9 -> 2000 | R9: 2000
A10: BRYSON KIPCHUMBA | B10: 0143 | C10: D | E10: 11500 | F10: =E10 -> 11500 | G10: =H10+D10-F10 -> 0 | H10: 11500 | I10: =G10 -> 0 | J10: 4000 | K10: =J10 -> 4000 | L10: =M10+I10-K10 -> 0 | M10: 4000 | N10: =L10 -> 0 | O10: 2000 | P10: =O10 -> 2000 | Q10: =N10+R10-P10 -> 0 | R10: 2000
A11: LINUS KIPTOO | B11: 0144 | C11: D | E11: 9000 | F11: =E11 -> 9000 | G11: =H11+D11-F11 -> 2500 | H11: 11500 | I11: =G11 -> 2500 | J11: 6500 | K11: =J11 -> 6500 | L11: =M11+I11-K11 -> 0 | M11: 4000 | N11: =L11 -> 0 | P11: =O11 -> 0 | Q11: =N11+R11-P11 -> 2000 | R11: 2000
A12: ABEL KIMUTAI | B12: 0145 | C12: D | E12: 11500 | F12: =E12 -> 11500 | G12: =H12+D12-F12 -> 0 | H12: 11500 | I12: =G12 -> 0 | J12: 4000 | K12: =J12 -> 4000 | L12: =M12+I12-K12 -> 0 | M12: 4000 | N12: =L12 -> 0 | P12: =O12 -> 0 | Q12: =N12+R12-P12 -> 2000 | R12: 2000
A13: FIDEL KIPRUTO TANUI | B13: 0146 | C13: D | D13: 50 | E13: 8000 | F13: =E13 -> 8000 | G13: =H13+D13-F13 -> 3550 | H13: 11500 | I13: =G13 -> 3550 | J13: 4000 | K13: =J13 -> 4000 | L13: =M13+I13-K13 -> 3550 | M13: 4000 | N13: =L13 -> 3550 | P13: =O13 -> 0 | Q13: =N13+R13-P13 -> 5550 | R13: 2000
A14: JAYDEN KIGEN | B14: 0147 | C14: D | D14: 3250 | F14: =E14 -> 0 | G14: =H14+D14-F14 -> 14750 | H14: 11500 | I14: =G14 -> 14750 | K14: =J14 -> 0 | L14: =M14+I14-K14 -> 18750 | M14: 4000 | N14: =L14 -> 18750 | P14: =O14 -> 0 | Q14: =N14+R14-P14 -> 18750 | R14: 0
A15: AMON KIPCHIRHIR | B15: 0148 | C15: D | E15: 11500 | F15: =E15 -> 11500 | G15: =H15+D15-F15 -> 0 | H15: 11500 | I15: =G15 -> 0 | J15: 4000 | K15: =J15 -> 4000 | L15: =M15+I15-K15 -> 0 | M15: 4000 | N15: =L15 -> 0 | P15: =O15 -> 0 | Q15: =N15+R15-P15 -> 2000 | R15: 2000
A16: DEBRA CHEROP | B16: 0149 | C16: D | E16: 11500 | F16: =E16 -> 11500 | G16: =H16+D16-F16 -> 0 | H16: 11500 | I16: =G16 -> 0 | J16: 4000 | K16: =J16 -> 4000 | L16: =M16+I16-K16 -> 0 | M16: 4000 | N16: =L16 -> 0 | P16: =O16 -> 0 | Q16: =N16+R16-P16 -> 2000 | R16: 2000
A17: BLESSING JEPKOECH KIPROP | B17: 0150 | C17: D | D17: 2975 | E17: 9535 | F17: =E17 -> 9535 | G17: =H17+D17-F17 -> 4940 | H17: 11500 | I17: =G17 -> 4940 | J17: 2410 | K17: =J17 -> 2410 | L17: =M17+I17-K17 -> 6530 | M17: 4000 | N17: =L17 -> 6530 | O17: 3500 | P17: =O17 -> 3500 | Q17: =N17+R17-P17 -> 5030 | R17: 2000
A18: SHIRLEEN JEPCHUMBA KEMEI | B18: 0151 | C18: D | F18: =E18 -> 0 | G18: =H18+D18-F18 -> 11500 | H18: 11500 | I18: =G18 -> 11500 | K18: =J18 -> 0 | L18: =M18+I18-K18 -> 11500 | M18: 0 | N18: =L18 -> 11500 | P18: =O18 -> 0 | Q18: =N18+R18-P18 -> 11500 | R18: 0
A19: FAITH JEPKEMEI YEGO | B19: 0152 | C19: D | D19: 7500 | E19: 7800 | F19: =E19 -> 7800 | G19: =H19+D19-F19 -> 7750 | H19: 8050 | I19: =G19 -> 7750 | J19: 6000 | K19: =J19 -> 6000 | L19: =M19+I19-K19 -> 4550 | M19: 2800 | N19: =L19 -> 4550 | O19: 2900 | P19: =O19 -> 2900 | Q19: =N19+R19-P19 -> 3050 | R19: 1400
A20: BLESSING JEBICHII | B20: 0153 | C20: D | E20: 11500 | F20: =E20 -> 11500 | G20: =H20+D20-F20 -> 0 | H20: 11500 | I20: =G20 -> 0 | J20: =2800+1200 -> 4000 | K20: =J20 -> 4000 | L20: =M20+I20-K20 -> 0 | M20: 4000 | N20: =L20 -> 0 | O20: 1000 | P20: =O20 -> 1000 | Q20: =N20+R20-P20 -> 1000 | R20: 2000
A21: BLESSING JEROTICH | B21: 0154 | C21: D | E21: 8350 | F21: =E21 -> 8350 | G21: =H21+D21-F21 -> 3150 | H21: 11500 | I21: =G21 -> 3150 | J21: =1000+3600 -> 4600 | K21: =J21 -> 4600 | L21: =M21+I21-K21 -> 2550 | M21: 4000 | N21: =L21 -> 2550 | O21: 900 | P21: =O21 -> 900 | Q21: =N21+R21-P21 -> 3650 | R21: 2000
A22: ABIGAEL JERUTO | B22: 0155 | C22: D | E22: 11500 | F22: =E22 -> 11500 | G22: =H22+D22-F22 -> 0 | H22: 11500 | I22: =G22 -> 0 | J22: 4000 | K22: =J22 -> 4000 | L22: =M22+I22-K22 -> 0 | M22: 4000 | N22: =L22 -> 0 | P22: =O22 -> 0 | Q22: =N22+R22-P22 -> 2000 | R22: 2000
A23: BLESSING JEPCHUMBA TANUI | B23: 0156 | C23: D | F23: =E23 -> 0 | G23: =H23+D23-F23 -> 11500 | H23: 11500 | I23: =G23 -> 11500 | K23: =J23 -> 0 | L23: =M23+I23-K23 -> 11500 | M23: 0 | N23: =L23 -> 11500 | P23: =O23 -> 0 | Q23: =N23+R23-P23 -> 11500 | R23: 0
